Workbook

Sheet B1. B
B2: Boron
B3: (quantities are representative of quantified form listed below, unless otherwise specified)
B5: Byproduct Information
B6: Chemical Formula of Quantified Form: | C6: B2O3
B7: USGS Mineral Commodity Summary Page: | C7: Boron
B8: Demand Data Market Specificity: | C8: Byproduct
B9: Demand Data Resolution: | C9: Domestic
B13: Major End-Use Markets1
B14: Assigned End-Use Category | C14: End-Use | D14: Demand (kt) | E14: % of Demand | G14: The most recent Mineral Commodity Summary with quantified shares of consumption by end use is from 2024, which reports that the glass and ceramics industries account for 65% of total borates consumption, so we adopt this value. All other end uses are consolidated into "Miscellaneous Manufacturing".
B15: Glass Manufacturing | C15: Glass and ceramics | D15: – | E15: 0.65
B16: Miscellaneous Manufacturing | C16: Abrasives, cleaning products, insecticides, insulation, semiconductor production | D16: – | E16: 0.35
B17: (1) Source: USGS Mineral Commodity Summaries 2024, Boron
B21: Domestic Demand
B22: Calculation Schema: | C22: Trade Balance Estimate
B23: Description | C23: Units | D23: 2021 | E23: 2022 | F23: 2023 | G23: 2024 | H23: 2025
B24: Domestic Production1 | C24: kt | D24: =J41 -> 488 | E24: =K41 -> 532 | F24: =L41 -> 495 | G24: =M41 -> 504 | H24: =N41 -> 502
B25: Imports for Consumption2 | C25: kt | D25: =E55 -> 95.719809 | E25: =F55 -> 74.915214 | F25: =G55 -> 59.426397 | G25: =H55 -> 63.899414 | H25: =I55 -> 74.019796
B26: Domestic Exports3 | C26: kt | D26: =E62 -> 47.223602 | E26: =F62 -> 41.768599 | F26: =G62 -> 58.258883 | G26: =H62 -> 57.467468 | H26: =I62 -> 39.605678
B27: Consumption, apparent4 | C27: kt | D27: =D24+D25-D26 -> 536.49621 | E27: =E24+E25-E26 -> 565.14661 | F27: =F24+F25-F26 -> 496.16751 | G27: =G24+G25-G26 -> 510.43195 | H27: =H24+H25-H26 -> 536.41412
B28: (1) See "Domestic Production" section below
B29: (2) See "Imports and Exports" section below
B30: (3) See "Imports and Exports" section below
B31: (4) Production + Imports – Exports
B33: Demand Calculations
B34: Domestic Production
B35: To avoid disclosing proprietary information, USGS has withheld boron consumption estimates since 2006. Domestic boron production, however, is entirely attributable to two companies, chiefly U.S. Borax, a subsidiary of Rio Tinto responsible for 30% of global boron supply.1 As a publicly traded corporation, Rio Tinto publishes annual reports that disclose total production quantities for their mined metals and minerals. In the years for which both USGS and U.S. Borax production values are available (2000-2005), these values are quite similar (within 15%), supporting the assumption that U.S. Borax’s production of borates constitutes a vast majority of domestic production. Under this assumption, we adopt U.S. Borax production volumes as values for domestic boron production for 2021-2025.
B36: (1) Source: U.S. Borax
B38: Boron Production in the United States
B39: Description | C39: Units | D39: 2000 | E39: 2001 | F39: 2002 | G39: 2003 | H39: 2004 | I39: 2005 | J39: 2021 | K39: 2022 | L39: 2023 | M39: 2024 | N39: 2025
B40: Total Domestic Production1 | C40: kt | D40: 546 | E40: 536 | F40: 543 | G40: 605 | H40: 637 | I40: 612 | J40: – | K40: – | L40: – | M40: – | N40: –
B41: U.S. Borax Production2 | C41: kt | D41: 570 | E41: 549 | F41: 514 | G41: 541 | H41: 543 | I41: 540 | J41: 488 | K41: 532 | L41: 495 | M41: 504 | N41: 502
B42: (1) Source: USGS Mineral Commodity Summaries 2002-2007, Boron
B43: (2) Source: Annual Reports, Rio Tinto Corporation. Retrieved from the U.S. Securities and Exchange Commission's Electronic Data Gathering, Analysis, and Retrieval (EDGAR) system for RIO TINTO PLC (CIK 0000863064).
B45: Imports and Exports
B46: USITC tracks trade of boron products and minerals, rather than boron itself. We extract import/export quantities for key boron products and minerals from a combination of USITC statistics (for boron products) and USGS Mineral Commodity Summaries (for boron minerals). Note that these quantities are in units of gross weight of product, and are thus converted to kt of B2O3 when calculating the total.
B48: Imports for Consumption, Boron Products | K48: Assumed B2O3 content by boron product
B49: Product Name | C49: Units | D49: HTS Code | E49: 2021 | F49: 2022 | G49: 2023 | H49: 2024 | I49: 2025 | K49: Product Name | L49: Chemical Composition | M49: % B2O3
B50: Anhydrous Refined Borax1 | C50: kt gross weight | D50: 2840.11.0000 | E50: =_xlfn.XLOOKUP(_xlfn.CONCAT(_xlfn.TEXTSPLIT($D50,".")), 'S1. USITC Imports'!$B:$B,'S1. USITC Imports'!$J:$J)*_xlfn.XLOOKUP(_xlfn.CONCAT(_xlfn.TEXTSPLIT($D50,".")), 'S1. USITC Imports'!$B:$B,'S1. USITC Imports'!E:E) -> 6.01942 | F50: =_xlfn.XLOOKUP(_xlfn.CONCAT(_xlfn.TEXTSPLIT($D50,".")), 'S1. USITC Imports'!$B:$B,'S1. USITC Imports'!$J:$J)*_xlfn.XLOOKUP(_xlfn.CONCAT(_xlfn.TEXTSPLIT($D50,".")), 'S1. USITC Imports'!$B:$B,'S1. USITC Imports'!F:F) -> 5.375388 | G50: =_xlfn.XLOOKUP(_xlfn.CONCAT(_xlfn.TEXTSPLIT($D50,".")), 'S1. USITC Imports'!$B:$B,'S1. USITC Imports'!$J:$J)*_xlfn.XLOOKUP(_xlfn.CONCAT(_xlfn.TEXTSPLIT($D50,".")), 'S1. USITC Imports'!$B:$B,'S1. USITC Imports'!G:G) -> 3.15804 | H50: =_xlfn.XLOOKUP(_xlfn.CONCAT(_xlfn.TEXTSPLIT($D50,".")), 'S1. USITC Imports'!$B:$B,'S1. USITC Imports'!$J:$J)*_xlfn.XLOOKUP(_xlfn.CONCAT(_xlfn.TEXTSPLIT($D50,".")), 'S1. USITC Imports'!$B:$B,'S1. USITC Imports'!H:H) -> 2.955172 | I50: =_xlfn.XLOOKUP(_xlfn.CONCAT(_xlfn.TEXTSPLIT($D50,".")), 'S1. USITC Imports'!$B:$B,'S1. USITC Imports'!$J:$J)*_xlfn.XLOOKUP(_xlfn.CONCAT(_xlfn.TEXTSPLIT($D50,".")), 'S1. USITC Imports'!$B:$B,'S1. USITC Imports'!I:I) -> 4.371018 | K50: Anhydrous Refined Borax1 | L50: Na2B4O7 | M50: 0.35
B51: Non-Anhydrous Refined Borax1 | C51: kt gross weight | D51: 2840.19.0000 | E51: =_xlfn.XLOOKUP(_xlfn.CONCAT(_xlfn.TEXTSPLIT($D51,".")), 'S1. USITC Imports'!$B:$B,'S1. USITC Imports'!$J:$J)*_xlfn.XLOOKUP(_xlfn.CONCAT(_xlfn.TEXTSPLIT($D51,".")), 'S1. USITC Imports'!$B:$B,'S1. USITC Imports'!E:E) -> 225.92562 | F51: =_xlfn.XLOOKUP(_xlfn.CONCAT(_xlfn.TEXTSPLIT($D51,".")), 'S1. USITC Imports'!$B:$B,'S1. USITC Imports'!$J:$J)*_xlfn.XLOOKUP(_xlfn.CONCAT(_xlfn.TEXTSPLIT($D51,".")), 'S1. USITC Imports'!$B:$B,'S1. USITC Imports'!F:F) -> 162.30749 | G51: =_xlfn.XLOOKUP(_xlfn.CONCAT(_xlfn.TEXTSPLIT($D51,".")), 'S1. USITC Imports'!$B:$B,'S1. USITC Imports'!$J:$J)*_xlfn.XLOOKUP(_xlfn.CONCAT(_xlfn.TEXTSPLIT($D51,".")), 'S1. USITC Imports'!$B:$B,'S1. USITC Imports'!G:G) -> 152.40779 | H51: =_xlfn.XLOOKUP(_xlfn.CONCAT(_xlfn.TEXTSPLIT($D51,".")), 'S1. USITC Imports'!$B:$B,'S1. USITC Imports'!$J:$J)*_xlfn.XLOOKUP(_xlfn.CONCAT(_xlfn.TEXTSPLIT($D51,".")), 'S1. USITC Imports'!$B:$B,'S1. USITC Imports'!H:H) -> 147.19724 | I51: =_xlfn.XLOOKUP(_xlfn.CONCAT(_xlfn.TEXTSPLIT($D51,".")), 'S1. USITC Imports'!$B:$B,'S1. USITC Imports'!$J:$J)*_xlfn.XLOOKUP(_xlfn.CONCAT(_xlfn.TEXTSPLIT($D51,".")), 'S1. USITC Imports'!$B:$B,'S1. USITC Imports'!I:I) -> 143.31122 | K51: Non-Anhydrous Refined Borax1 | L51: Na2B4O7 · 10H2O | M51: 0.18
B52: Boric Acid1 | C52: kt gross weight | D52: 2810.00.0000 | E52: =_xlfn.XLOOKUP(_xlfn.CONCAT(_xlfn.TEXTSPLIT($D52,".")), 'S1. USITC Imports'!$B:$B,'S1. USITC Imports'!$J:$J)*_xlfn.XLOOKUP(_xlfn.CONCAT(_xlfn.TEXTSPLIT($D52,".")), 'S1. USITC Imports'!$B:$B,'S1. USITC Imports'!E:E) -> 54.19 | F52: =_xlfn.XLOOKUP(_xlfn.CONCAT(_xlfn.TEXTSPLIT($D52,".")), 'S1. USITC Imports'!$B:$B,'S1. USITC Imports'!$J:$J)*_xlfn.XLOOKUP(_xlfn.CONCAT(_xlfn.TEXTSPLIT($D52,".")), 'S1. USITC Imports'!$B:$B,'S1. USITC Imports'!F:F) -> 48.158 | G52: =_xlfn.XLOOKUP(_xlfn.CONCAT(_xlfn.TEXTSPLIT($D52,".")), 'S1. USITC Imports'!$B:$B,'S1. USITC Imports'!$J:$J)*_xlfn.XLOOKUP(_xlfn.CONCAT(_xlfn.TEXTSPLIT($D52,".")), 'S1. USITC Imports'!$B:$B,'S1. USITC Imports'!G:G) -> 37.978 | H52: =_xlfn.XLOOKUP(_xlfn.CONCAT(_xlfn.TEXTSPLIT($D52,".")), 'S1. USITC Imports'!$B:$B,'S1. USITC Imports'!$J:$J)*_xlfn.XLOOKUP(_xlfn.CONCAT(_xlfn.TEXTSPLIT($D52,".")), 'S1. USITC Imports'!$B:$B,'S1. USITC Imports'!H:H) -> 42.535 | I52: =_xlfn.XLOOKUP(_xlfn.CONCAT(_xlfn.TEXTSPLIT($D52,".")), 'S1. USITC Imports'!$B:$B,'S1. USITC Imports'!$J:$J)*_xlfn.XLOOKUP(_xlfn.CONCAT(_xlfn.TEXTSPLIT($D52,".")), 'S1. USITC Imports'!$B:$B,'S1. USITC Imports'!I:I) -> 52.382 | K52: Boric Acid2 | L52: H3BO3 | M52: 0.56
...

Sheet B2. BaSO4
B2: Barium Sulfate
B3: (quantities are representative of quantified form listed below, unless otherwise specified)
B5: Byproduct Information
B6: Chemical Formula of Quantified Form: | C6: BaSO4
B7: USGS Mineral Commodity Summary Page: | C7: Barite
B8: Demand Data Market Specificity: | C8: Byproduct
B9: Demand Data Resolution: | C9: Domestic
B13: Major End-Use Markets1
B14: Assigned End-Use Category | C14: End-Use | D14: Demand (kt) | E14: % of Demand | G14: More than 90% of barite sold in the US is used as a weighting agent in oil and gas well drilling fluids. Barite also has several other applications in materials manufacturing (e.g. paints, plastics, rubber, etc.), which we collapse into the “Miscellaneous Manufacturing” category.
B15: Oil and Gas Drilling | C15: Weighting agent in oil and gas drilling fluids | D15: – | E15: 0.9
B16: Miscellaneous Manufacturing | C16: Filler, extender, weighting agent; metal casting; concrete aggregate; X-ray contrast | D16: – | E16: 0.1
B17: (1) Source: USGS Mineral Commodity Summaries 2026, Barite
B21: Domestic Demand
B22: Calculation Schema: | C22: Trade Balance Estimate
B23: Description | C23: Units | D23: 2021 | E23: 2022 | F23: 2023 | G23: 2024 | H23: 2025
B24: Domestic Production1 | C24: kt | D24: =D39 -> 1670 | E24: =E39 -> 2220 | F24: =F39 -> 2260 | G24: =G39 -> 2280 | H24: =H39 -> 2300
B25: Imports for Consumption2 | C25: kt | D25: =E48 -> 1202.236 | E25: =F48 -> 1683.152 | F25: =G48 -> 1413.413 | G25: =H48 -> 1440.243 | H25: =I48 -> 1465.785
B26: Domestic Exports3 | C26: kt | D26: =E55 -> 61.577952 | E26: =F55 -> 86.500848 | F26: =G55 -> 74.706951 | G26: =H55 -> 65.029602 | H26: =I55 -> 63.938504
B27: Consumption, apparent4 | C27: kt | D27: =D24+D25-D26 -> 2810.658 | E27: =E24+E25-E26 -> 3816.6512 | F27: =F24+F25-F26 -> 3598.706 | G27: =G24+G25-G26 -> 3655.2134 | H27: =H24+H25-H26 -> 3701.8465
B28: (1) See "Domestic Production" section below
B29: (2) See "Imports and Exports" section below
B30: (3) See "Imports and Exports" section below
B31: (4) Production + Imports – Exports
B33: Demand Calculations
B34: Domestic Production
B35: To avoid disclosing proprietary information, USGS has withheld total barite consumption (crude + ground and crushed) estimates since 2017. They do, however, report production of ground and crushed barite, which is the form of barite more relevant in this context.
B37: Domestic Production, Crushed and Ground Barite
B38: Description | C38: Units | D38: 2021 | E38: 2022 | F38: 2023 | G38: 2024 | H38: 2025
B39: Production1 | C39: kt | D39: 1670 | E39: 2220 | F39: 2260 | G39: 2280 | H39: 2300
B40: (1) Source: USGS Mineral Commodity Summaries 2026, Barite
B42: Imports and Exports
B43: While USITC tracks imports for ground barium sulfate (HTS Code 2511.10.1000), barium sulfate exports are tracked through HTS Codes 2511.10.0000 (Natural Barium Sulfate) and 2833.27.0000 (Barium Sulfate), which would include, but not be exclusive to, ground barium sulfate. Nevertheless, we treat these exports as representative of ground barium sulfate, which should have minimal affect on our consumption estimates, given the relative insignificance of export quantities in this trade balance.
B45: Imports for Consumption, Barium Sulfate
B46: Product Name | C46: Units | D46: HTS Code | E46: 2021 | F46: 2022 | G46: 2023 | H46: 2024 | I46: 2025
B47: Natural Barium Sulfate, Ground1 | C47: kt | D47: 2511.10.1000 | E47: =_xlfn.XLOOKUP(_xlfn.CONCAT(_xlfn.TEXTSPLIT($D47,".")), 'S1. USITC Imports'!$B:$B,'S1. USITC Imports'!$J:$J)*_xlfn.XLOOKUP(_xlfn.CONCAT(_xlfn.TEXTSPLIT($D47,".")), 'S1. USITC Imports'!$B:$B,'S1. USITC Imports'!E:E) -> 1202.236 | F47: =_xlfn.XLOOKUP(_xlfn.CONCAT(_xlfn.TEXTSPLIT($D47,".")), 'S1. USITC Imports'!$B:$B,'S1. USITC Imports'!$J:$J)*_xlfn.XLOOKUP(_xlfn.CONCAT(_xlfn.TEXTSPLIT($D47,".")), 'S1. USITC Imports'!$B:$B,'S1. USITC Imports'!F:F) -> 1683.152 | G47: =_xlfn.XLOOKUP(_xlfn.CONCAT(_xlfn.TEXTSPLIT($D47,".")), 'S1. USITC Imports'!$B:$B,'S1. USITC Imports'!$J:$J)*_xlfn.XLOOKUP(_xlfn.CONCAT(_xlfn.TEXTSPLIT($D47,".")), 'S1. USITC Imports'!$B:$B,'S1. USITC Imports'!G:G) -> 1413.413 | H47: =_xlfn.XLOOKUP(_xlfn.CONCAT(_xlfn.TEXTSPLIT($D47,".")), 'S1. USITC Imports'!$B:$B,'S1. USITC Imports'!$J:$J)*_xlfn.XLOOKUP(_xlfn.CONCAT(_xlfn.TEXTSPLIT($D47,".")), 'S1. USITC Imports'!$B:$B,'S1. USITC Imports'!H:H) -> 1440.243 | I47: =_xlfn.XLOOKUP(_xlfn.CONCAT(_xlfn.TEXTSPLIT($D47,".")), 'S1. USITC Imports'!$B:$B,'S1. USITC Imports'!$J:$J)*_xlfn.XLOOKUP(_xlfn.CONCAT(_xlfn.TEXTSPLIT($D47,".")), 'S1. USITC Imports'!$B:$B,'S1. USITC Imports'!I:I) -> 1465.785
B48: Total | C48: kt | D48: – | E48: =E47 -> 1202.236 | F48: =F47 -> 1683.152 | G48: =G47 -> 1413.413 | H48: =H47 -> 1440.243 | I48: =I47 -> 1465.785
B49: (1) Source: USITC DataWeb, Imports for Consumption
B51: Domestic Exports, Boron Products
B52: Product Name | C52: Units | D52: HTS Code | E52: 2021 | F52: 2022 | G52: 2023 | H52: 2024 | I52: 2025
B53: Natural Barium Sulfate1 | C53: kt | D53: 2511.10.0000 | E53: =_xlfn.XLOOKUP(_xlfn.CONCAT(_xlfn.TEXTSPLIT($D53,".")), 'S2. USITC Exports'!$B:$B,'S2. USITC Exports'!$J:$J)*_xlfn.XLOOKUP(_xlfn.CONCAT(_xlfn.TEXTSPLIT($D53,".")), 'S2. USITC Exports'!$B:$B,'S2. USITC Exports'!E:E) -> 53.05 | F53: =_xlfn.XLOOKUP(_xlfn.CONCAT(_xlfn.TEXTSPLIT($D53,".")), 'S2. USITC Exports'!$B:$B,'S2. USITC Exports'!$J:$J)*_xlfn.XLOOKUP(_xlfn.CONCAT(_xlfn.TEXTSPLIT($D53,".")), 'S2. USITC Exports'!$B:$B,'S2. USITC Exports'!F:F) -> 77.075 | G53: =_xlfn.XLOOKUP(_xlfn.CONCAT(_xlfn.TEXTSPLIT($D53,".")), 'S2. USITC Exports'!$B:$B,'S2. USITC Exports'!$J:$J)*_xlfn.XLOOKUP(_xlfn.CONCAT(_xlfn.TEXTSPLIT($D53,".")), 'S2. USITC Exports'!$B:$B,'S2. USITC Exports'!G:G) -> 61.975 | H53: =_xlfn.XLOOKUP(_xlfn.CONCAT(_xlfn.TEXTSPLIT($D53,".")), 'S2. USITC Exports'!$B:$B,'S2. USITC Exports'!$J:$J)*_xlfn.XLOOKUP(_xlfn.CONCAT(_xlfn.TEXTSPLIT($D53,".")), 'S2. USITC Exports'!$B:$B,'S2. USITC Exports'!H:H) -> 53.134 | I53: =_xlfn.XLOOKUP(_xlfn.CONCAT(_xlfn.TEXTSPLIT($D53,".")), 'S2. USITC Exports'!$B:$B,'S2. USITC Exports'!$J:$J)*_xlfn.XLOOKUP(_xlfn.CONCAT(_xlfn.TEXTSPLIT($D53,".")), 'S2. USITC Exports'!$B:$B,'S2. USITC Exports'!I:I) -> 53.879
...

Sheet B3. Br
B2: Bromine
B3: (quantities are representative of quantified form listed below, unless otherwise specified)
B5: Byproduct Information
B6: Chemical Formula of Quantified Form: | C6: Br
B7: USGS Mineral Commodity Summary Page: | C7: Bromine
B8: Demand Data Market Specificity: | C8: Byproduct
B9: Demand Data Resolution: | C9: Domestic
B13: Major End-Use Markets1
B14: Assigned End-Use Category | C14: End-Use | D14: Demand (kt) | E14: % of Demand | G14: The 2026 USGS Mineral Commodity Summary for Bromine lists production of brominated flame retardants (BFRs) and clear brine drilling fluids as the leading global applications of bromine, but do not provide quantitative market shares for any end use. We instead derive percent of demand by end use from Ullmann’s Encyclopedia for Industrial Chemistry, which lists a similar set of end uses on the global scale. We assume that domestic bromine market shares by end use mirror global proportions, with the exception of pesticide manufacturing, as the EPA has phased out production and consumption of methyl bromide fumigants due to ozone depletion concerns.1 After removal of pesticide manufacturing, we reallocate all other market shares to total 100%.
B15: Miscellaneous Chemical Manufacturing | C15: Flame retardant | D15: 483000 | E15: =D15/SUM($D$15:$D$19) -> 0.5894557
B16: Oil and Gas Drilling | C16: Drilling fluids | D16: 103500 | E16: =D16/SUM($D$15:$D$19) -> 0.12631194
B17: Organic Chemical Manufacturing | C17: Organic synthesis | D17: 86300 | E17: =D17/SUM($D$15:$D$19) -> 0.10532097
B18: Pharmaceutical Manufacturing | C18: Pharmaceuticals | D18: 77600 | E18: =D18/SUM($D$15:$D$19) -> 0.094703442
B19: Industrial Water Treatment | C19: Water treatment | D19: 69000 | E19: =D19/SUM($D$15:$D$19) -> 0.084207957
B20: (1) Source: Ullmann's Encyclopedia for Industrial Chemistry, Bromine | G20: (1) U.S. Environmental Protection Agency
B24: Domestic Demand
B25: Calculation Schema: | C25: Trade Balance Estimate
B26: Description | C26: Units | D26: 2021 | E26: 2022 | F26: 2023 | G26: 2024 | H26: 2025
B27: Domestic Production1 | C27: kt | D27: =D47 -> 201 | E27: =E47 -> 203 | F27: =F47 -> 195 | G27: =G47 -> 195 | H27: =H47 -> 199
B28: Imports for Consumption2 | C28: kt | D28: =D55 -> 27.2 | E28: =E55 -> 36.5 | F28: =F55 -> 50.8 | G28: =G55 -> 58.3 | H28: =H55 -> 40
B29: Domestic Exports3 | C29: kt | D29: =D60 -> 27.9 | E29: =E60 -> 19.4 | F29: =F60 -> 38.9 | G29: =G60 -> 33.8 | H29: =H60 -> 33
B30: Consumption, apparent4 | C30: kt | D30: =D27+D28-D29 -> 200.3 | E30: =E27+E28-E29 -> 220.1 | F30: =F27+F28-F29 -> 206.9 | G30: =G27+G28-G29 -> 219.5 | H30: =H27+H28-H29 -> 206
B31: (1) See "Domestic Production" section below
B32: (2) See "Imports and Exports" section below
B33: (3) See "Imports and Exports" section below
B34: (4) Production + Imports – Exports
B36: Demand Calculations
B37: Domestic Production
B38: To avoid disclosing proprietary information, USGS has withheld bromine consumption and production estimates since 2006. Domestic bromine production, however, is entirely attributable to two companies in Arkansas: Albemarle Corporation and Chemtura.1, 2 Since 2020, Albemarle Corporation has disclosed its annual aggregate bromine production in the US in its annual reports. Chemtura, on the other hand, was acquired by German company LANXESS AG in 2017 and withholds its production data as proprietary.3 The most recent measure of both companies’ annual bromine production capacities reported a value of 148 kt for Albemarle and 130 kt for Chemtura.2 To remain conservative in our consumption estimates, we assume Chemtura's annual production is equal to their capacity, and add it to reported Albemarle production to get total domestic production of Bromine.
B39: (1) Source: USGS Mineral Commodity Summaries 2026, Bromine
B40: (2) Source: Arkansas Geological Survey
B41: (3) Source: LANXESS AG
B43: Domestic Production, Bromine
B44: Description | C44: Units | D44: 2021 | E44: 2022 | F44: 2023 | G44: 2024 | H44: 2025
B45: Albemarle Corporation Production1 | C45: kt | D45: 71 | E45: 73 | F45: 65 | G45: 65 | H45: 69
B46: Assumed Chemtura Production2 | C46: kt | D46: 130 | E46: 130 | F46: 130 | G46: 130 | H46: 130
B47: Total Domestic Production | C47: kt | D47: =D45+D46 -> 201 | E47: =E45+E46 -> 203 | F47: =F45+F46 -> 195 | G47: =G45+G46 -> 195 | H47: =H45+H46 -> 199
B48: (1) Source: Annual Reports, Albemarle Corporation. Retrieved from the U.S. Securities and Exchange Commission's Electronic Data Gathering, Analysis, and Retrieval (EDGAR) system for ALBEMARLE CORP (CIK 0000915913).
B49: (2) Assumed based on reported capacity of Chemtura bromine facilities (Arkansas Geological Survey)
B51: Imports and Exports
...

Sheet B4. CaCO3
B2: Calcium Carbonate
B3: (quantities are representative of quantified form listed below, unless otherwise specified)
B5: Byproduct Information
B6: Chemical Formula of Quantified Form: | C6: CaCO3
B7: USGS Mineral Commodity Summary Page: | C7: Stone (Crushed)
B8: Demand Data Market Specificity: | C8: Byproduct-Market
B9: Demand Data Resolution: | C9: State
B13: Major End-Use Markets1
B14: Assigned End-Use Category | C14: End-Use | D14: Demand (kt) | E14: % of Demand | G14: Major end use markets for limestone (CaCO3) are reported and quantified in Table 10 of the most recent USGS Minerals Yearbook (2023) for Crushed Stone. We consider all end uses listed for limestone with the exception of Construction Aggregate, as precipitated calcium carbonate from brines would not be sufficiently coarse for this end use. With shares of remaining demand less than 5%, agricultural uses and sulfur dioxide removal are consolidated into the “Other” category and ignored, leaving Cement and Lime Manufacturing as the key domestic end uses of (precipitated) calcium carbonate.
B15: Other | C15: Agricultural uses | D15: 13004 | E15: =D15/SUM($D$15:$D$19) -> 0.018516251
B16: Cement Manufacturing | C16: Cement Manufacture | D16: 110000 | E16: =D16/SUM($D$15:$D$19) -> 0.15662778
B17: Lime Manufacturing | C17: Lime Manufacture | D17: 32500 | E17: =D17/SUM($D$15:$D$19) -> 0.046276388
B18: Other | C18: Sulfur oxide removal | D18: 4120 | E18: =D18/SUM($D$15:$D$19) -> 0.0058664221
B19: Other | C19: Miscellaneous and unspecified uses | D19: 542678 | E19: =D19/SUM($D$15:$D$19) -> 0.77271316
B20: (1) Source: USGS Minerals Yearbook 2023, Stone (Crushed)
B26: State-Level Demand by End-Use
B27: In all of its publications, USGS typically groups limestone and dolomite statistics, making it difficult to extract an isolated demand for limestone. Within these key end use markets (cement and lime manufacturing), however, both limestone and dolomite are suitable, interchangeable raw materials, so their aggregate demand in these markets can still be considered an upper bound on calcium carbonate demand.
B28: USGS Minerals Yearbook, Stone (Crushed) reports limestone and dolomite sale/use at a state level for both cement and lime manufacturing for years 2021, 2022, and 2023. Because imports/export volumes of all types of crushed stone are negligible compared to domestic production/consumption1, we use these values directly and distribute the total quantities withheld among the remaining states using the appropriate disaggregation proxies.
B29: For years 2024 and 2025, state level data is not yet available, so we disaggregate total byproduct-market demand using the same proxies. To estimate byproduct-market demand, we first assume that limestone and dolomite account for 70% of total crushed stone consumption in the US, a reasonable assumption given that limestone and dolomite account for 70% of domestic crushed stone production and imports and exports are relatively negligible compared to these volumes.1 We then calculate the fraction of total domestic demand attributable to each end use based on the table above.
B30: (1) Source: USGS Mineral Commodity Summaries 2026, Stone (Crushed)
B32: Cement Manufacturing1,2
B33: State | C33: Units | D33: 2021 | E33: 2022 | F33: 2023 | G33: 2024 | H33: 2025
B34: Alabama | C34: kt | D34: 5200 | E34: 4180 | F34: 4660 | G34: W | H34: W
B35: Alaska | C35: kt | D35: 0 | E35: 0 | F35: 0 | G35: W | H35: W
B36: Arizona | C36: kt | D36: W | E36: 3540 | F36: W | G36: W | H36: W
B37: Arkansas | C37: kt | D37: W | E37: W | F37: W | G37: W | H37: W
B38: California | C38: kt | D38: 12300 | E38: 12800 | F38: 12300 | G38: W | H38: W
B39: Colorado | C39: kt | D39: 1780 | E39: W | F39: 3140 | G39: W | H39: W
B40: Connecticut | C40: kt | D40: 0 | E40: 0 | F40: 0 | G40: W | H40: W
B41: Delaware | C41: kt | D41: 0 | E41: 0 | F41: 0 | G41: W | H41: W
B42: Florida | C42: kt | D42: 8580 | E42: 7370 | F42: 5370 | G42: W | H42: W
B43: Georgia | C43: kt | D43: 801 | E43: 617 | F43: 530 | G43: W | H43: W
B44: Hawaii | C44: kt | D44: 0 | E44: 0 | F44: 0 | G44: W | H44: W
B45: Idaho | C45: kt | D45: 0 | E45: 0 | F45: 0 | G45: W | H45: W
B46: Illinois | C46: kt | D46: W | E46: W | F46: W | G46: W | H46: W
B47: Indiana | C47: kt | D47: W | E47: 3250 | F47: 3520 | G47: W | H47: W
B48: Iowa | C48: kt | D48: 2170 | E48: 2130 | F48: 2150 | G48: W | H48: W
B49: Kansas | C49: kt | D49: W | E49: W | F49: W | G49: W | H49: W
B50: Kentucky | C50: kt | D50: 2040 | E50: 2000 | F50: 1770 | G50: W | H50: W
B51: Louisiana | C51: kt | D51: W | E51: 0 | F51: 0 | G51: W | H51: W
...

Sheet B5. CaF2
B2: Calcium Fluoride
B3: (quantities are representative of quantified form listed below, unless otherwise specified)
B5: Byproduct Information
B6: Chemical Formula of Quantified Form: | C6: CaF2
B7: USGS Mineral Commodity Summary Page: | C7: Fluorspar
B8: Demand Data Market Specificity: | C8: Byproduct
B9: Demand Data Resolution: | C9: Domestic
B13: Major End-Use Markets1
B14: Assigned End-Use Category | C14: End-Use | D14: Demand (kt) | E14: % of Demand | G14: Given the expected purity (high) and grain size (fine) of calcium fluoride recoverable from brines, we focus on acid-grade fluorspar, which is used almost exclusively to manufacture hyrofluoric acid.
B15: Hydrofluoric Acid Manufacturing | C15: HF production | D15: – | E15: 1
B16: (1) Source: USGS Mineral Commodity Summaries 2026, Fluorspar
B20: Domestic Demand
B21: Calculation Schema: | C21: Direct Report
B22: Description | C22: Units | D22: 2021 | E22: 2022 | F22: 2023 | G22: 2024 | H22: 2025 | J22: Because the US is 100% net import reliant for fluorspar, we use USGS-reported imports for consumption of acid grade fluorspar as our demand estimates.
B23: Consumpton, apparent, acid grade fluorspar1 | C23: kt | D23: 391 | E23: 448 | F23: 378 | G23: 372 | H23: 360
B24: (1) Source: USGS Mineral Commodity Summaries 2026, Fluorspar
B28: Pricing
B29: Description | C29: Units | D29: 2021 | E29: 2022 | F29: 2023 | G29: 2024 | H29: 2025
B30: Price, average unit value of imports, cost, insurance, and freight1 | C30: $/t | D30: 322 | E30: 387 | F30: 428 | G30: 464 | H30: 470
B31: (1) Source: USGS Mineral Commodity Summaries 2026, Fluorspar

Sheet B6. Ca(OH)2
B2: Calcium Hydroxide
B3: (quantities are representative of quantified form listed below, unless otherwise specified)
B5: Byproduct Information
B6: Chemical Formula of Quantified Form: | C6: Ca(OH)2
B7: USGS Mineral Commodity Summary Page: | C7: Lime
B8: Demand Data Market Specificity: | C8: Byproduct
B9: Demand Data Resolution: | C9: Domestic
B13: Major End-Use Markets1
B14: Assigned End-Use Category | C14: End-Use | D14: Demand (kt) | E14: % of Demand | G14: Major end use markets for hydrated/slaked lime (Ca(OH)2) are reported and quantified in Table 4 of the most recent USGS Minerals Yearbook for Lime (2023). We consider each listed end use at the highest level of granularity for which reasonable disaggregation proxies would still exist, and consolidate all end uses with a market share <5% into the “Other” category.
B15: Miscellaneous Chemical Manufacturing | C15: Chemical and Industrial | D15: 615 | E15: =D15/SUM(D$15:D$23) -> 0.2494929
B16: Miscellaneous Construction | C16: Asphalt, building uses, soil stabilization, etc. | D16: 878 | E16: =D16/SUM(D$15:D$23) -> 0.35618661
B17: Flue Gas Desulfurization | C17: Flue gas treatment | D17: 446 | E17: =D17/SUM(D$15:D$23) -> 0.18093306
B18: Wastewater Treatment | C18: Sludge treatment | D18: 128 | E18: =D18/SUM(D$15:D$23) -> 0.051926978
B19: Other | C19: Acid-mine drainage | D19: 47 | E19: =D19/SUM(D$15:D$23) -> 0.019066937
B20: Drinking Water Treatment | C20: Drinking water treatment | D20: 137 | E20: =D20/SUM(D$15:D$23) -> 0.055578093
B21: Other | C21: Wastewater treatment | D21: 108 | E21: =D21/SUM(D$15:D$23) -> 0.043813387
B22: Other | C22: Other environmental | D22: 43 | E22: =D22/SUM(D$15:D$23) -> 0.017444219
B23: Other | C23: Metallurgy | D23: 63 | E23: =D23/SUM(D$15:D$23) -> 0.025557809
B24: (1) Source: USGS Minerals Yearbook 2023, Lime
B28: Domestic Demand
B29: Calculation Schema: | C29: Indirect Report
B30: Description | C30: Units | D30: 2021 | E30: 2022 | F30: 2023 | G30: 2024 | H30: 2025 | J30: USGS reports total domestic lime consumption for years 2021-2025. We assume that roughly 15% of domestic lime consumption is in the form of hydrated lime (Ca(OH)2) versus quicklime (CaO), based on historical data, and scale down total lime consumption accordingly.
B31: Consumption, apparent, total lime1 | C31: kt | D31: 16600 | E31: 16800 | F31: 15800 | G31: 15000 | H31: 15000
B32: Assumed fraction of consumed lime attribuable to hydrated lime2 | C32: – | D32: 0.15 | E32: 0.15 | F32: 0.15 | G32: 0.15 | H32: 0.15
B33: Consumption, apparent, hydrated lime | C33: kt | D33: =D31*D32 -> 2490 | E33: =E31*E32 -> 2520 | F33: =F31*F32 -> 2370 | G33: =G31*G32 -> 2250 | H33: =H31*H32 -> 2250
B34: (1) Source: USGS Mineral Commodity Summaries 2026, Lime
B35: (2) Based on commercial lime sales data from Table 1 of USGS Minerals Yearbook 2023, Lime
B39: Pricing
B40: Description | C40: Units | D40: 2021 | E40: 2022 | F40: 2023 | G40: 2024 | H40: 2025
B41: Price, average value, at plant, hydrated lime1 | C41: $/t | D41: 158 | E41: 179.1 | F41: 234.6 | G41: 274.2 | H41: 280
B42: (1) Source: USGS Mineral Commodity Summaries 2026, Lime

Sheet B7. CaSO4
B2: Calcium Sulfate
B3: (quantities are representative of quantified form listed below, unless otherwise specified)
B5: Byproduct Information
B6: Chemical Formula of Quantified Form: | C6: CaSO4
B7: USGS Mineral Commodity Summary Page: | C7: Gypsum
B8: Demand Data Market Specificity: | C8: Byproduct
B9: Demand Data Resolution: | C9: Domestic
B13: Major End-Use Markets1
B14: Assigned End-Use Category | C14: End-Use | D14: Demand (kt) | E14: % of Demand | G14: Major end uses for gypsum (CaSO4) are reported and quantified in Table 3 of the most recent USGS Minerals Yearbook for Gypsum. We consider each listed end use at the highest level of granularity for which reasonable disaggregation proxies would still exist. Quantities of gypsum used in plaster are withheld but represented in “Other”, so we consolidate all calcined gypsum products into “Gypsum-Based Product Manufacturing”
B15: Cement Manufacturing | C15: Portland and masonry cement | D15: 4400 | E15: =D15/SUM(D$15:D$17) -> 0.11859838
B16: Miscellaneous Fertilizer Application | C16: Agriculture and other | D16: 14400 | E16: =D16/SUM(D$15:D$17) -> 0.38814016
B17: Gypsum-Based Product Manufacturing | C17: Plaster and prefabricated gypsum products | D17: 18300 | E17: =D17/SUM(D$15:D$17) -> 0.49326146
B18: (1) Source: USGS Minerals Yearbook 2023, Gypsum
B22: Domestic Demand
B23: Calculation Schema: | C23: Direct Report
B24: Description | C24: Units | D24: 2021 | E24: 2022 | F24: 2023 | G24: 2024 | H24: 2025
B25: Consumption, apparent1 | C25: kt | D25: 3200 | E25: 44600 | F25: 5800 | G25: 44900 | H25: 44000
B26: (1) Source: USGS Mineral Commodity Summaries 2026 Gypsum
B30: Pricing
B31: Description | C31: Units | D31: 2021 | E31: 2022 | F31: 2023 | G31: 2024 | H31: 2025
B32: Price, annual average, calcined, f.o.b. plant1 | C32: $/t | D32: 42 | E32: 50 | F32: 60 | G32: 60 | H32: 62
B33: (1) Source: USGS Mineral Commodity Summaries 2026 Gypsum

Sheet B8. HCl
B2: Hydrochloric Acid
B3: (quantities are representative of quantified form listed below, unless otherwise specified)
B5: Byproduct Information
B6: Chemical Formula of Quantified Form: | C6: HCl
B7: 8-Digit USITC HTS Number: | C7: 2806.10.00
B8: Demand Data Market Specificity: | C8: Byproduct
B9: Demand Data Resolution: | C9: Domestic
B13: Major End-Use Markets1
B14: Assigned End-Use Category | C14: End-Use | D14: Demand (kt) | E14: % of Demand
B15: Oil and Gas Well Acidification | C15: Oil and gas well acidification | D15: – | E15: 0.3
B16: Steel Pickling | C16: Steel pickling | D16: – | E16: 0.19
B17: Miscellaneous Manufacturing | C17: Food processing | D17: – | E17: 0.19
B18: Other | C18: Other | D18: – | E18: 0.32
B19: (1) Source: EPA Water Treatment Chemical Supply Chain Profile, Hydrochloric Acid
B23: Domestic Demand
B24: Calculation Schema: | C24: Trade Balance Estimate
B25: Description | C25: Units | D25: 2021 | E25: 2022 | F25: 2023 | G25: 2024 | H25: 2025
B26: Domestic Production1 | C26: kt | D26: =D43 -> 1214 | E26: =E43 -> 1158 | F26: =F43 -> 1191 | G26: =G43 -> 1200 | H26: =H43 -> 1200
B27: Imports for Consumption2 | C27: kt | D27: =E51 -> 328.677 | E27: =F51 -> 317.119 | F27: =G51 -> 350.072 | G27: =H51 -> 320.388 | H27: =I51 -> 270.188
B28: Domestic Exports3 | C28: kt | D28: =E56 -> 63.097 | E28: =F56 -> 84.293 | F28: =G56 -> 125.409 | G28: =H56 -> 120.031 | H28: =I56 -> 115.645
B29: Consumption, apparent4 | C29: kt | D29: =D26+D27-D28 -> 1479.58 | E29: =E26+E27-E28 -> 1390.826 | F29: =F26+F27-F28 -> 1415.663 | G29: =G26+G27-G28 -> 1400.357 | H29: =H26+H27-H28 -> 1354.543
B30: (1) See "Domestic Production" section below
B31: (2) See "Imports and Exports" section below
B32: (3) See "Imports and Exports" section below
B33: (4) Production + Imports – Exports
B35: Demand Calculations
B36: Domestic Production
B37: Domestic production of hydrochloric acid is tracked by the U.S. EPA under the Toxic Substances Control Act. We estimate domestic production by filtering 2024 CDR data for hydrochloric acid manufacturing production volumes, and sum the values for each year for which data is available (2021-2023). From this data, we see that hydrochloric acid production has remained relatively stable around 1,200 kt each year during this time period, so we adopt that as the production value for missing years (2024 and 2025).
B39: Domestic Production, Hydrochloric Acid
B40: Description | C40: Units | D40: 2021 | E40: 2022 | F40: 2023 | G40: 2024 | H40: 2025
B41: Reported domestic production1 | C41: kt | D41: 1214 | E41: 1158 | F41: 1191 | G41: – | H41: –
B42: Estimated domestic production2 | C42: kt | D42: – | E42: – | F42: – | G42: 1200 | H42: 1200
B43: Assumed domestic production | C43: kt | D43: =D41 -> 1214 | E43: =E41 -> 1158 | F43: =F41 -> 1191 | G43: =G42 -> 1200 | H43: =H42 -> 1200
B44: (1) Source: US EPA Chemical Data Reporting Data, 2024
B45: (2) Assumed based on patterns of consistent HCl production of ~1200 kt
B47: Imports and Exports
B49: Imports for Consumption, Hydrochloric Acid
B50: Product Name | C50: Units | D50: HTS Code | E50: 2021 | F50: 2022 | G50: 2023 | H50: 2024 | I50: 2025
B51: Hydrogen chloride (hydrochloric acid)1 | C51: kt | D51: 2806.10.0000 | E51: =_xlfn.XLOOKUP(_xlfn.CONCAT(_xlfn.TEXTSPLIT($D51,".")), 'S1. USITC Imports'!$B:$B,'S1. USITC Imports'!$J:$J)*_xlfn.XLOOKUP(_xlfn.CONCAT(_xlfn.TEXTSPLIT($D51,".")), 'S1. USITC Imports'!$B:$B,'S1. USITC Imports'!E:E) -> 328.677 | F51: =_xlfn.XLOOKUP(_xlfn.CONCAT(_xlfn.TEXTSPLIT($D51,".")), 'S1. USITC Imports'!$B:$B,'S1. USITC Imports'!$J:$J)*_xlfn.XLOOKUP(_xlfn.CONCAT(_xlfn.TEXTSPLIT($D51,".")), 'S1. USITC Imports'!$B:$B,'S1. USITC Imports'!F:F) -> 317.119 | G51: =_xlfn.XLOOKUP(_xlfn.CONCAT(_xlfn.TEXTSPLIT($D51,".")), 'S1. USITC Imports'!$B:$B,'S1. USITC Imports'!$J:$J)*_xlfn.XLOOKUP(_xlfn.CONCAT(_xlfn.TEXTSPLIT($D51,".")), 'S1. USITC Imports'!$B:$B,'S1. USITC Imports'!G:G) -> 350.072 | H51: =_xlfn.XLOOKUP(_xlfn.CONCAT(_xlfn.TEXTSPLIT($D51,".")), 'S1. USITC Imports'!$B:$B,'S1. USITC Imports'!$J:$J)*_xlfn.XLOOKUP(_xlfn.CONCAT(_xlfn.TEXTSPLIT($D51,".")), 'S1. USITC Imports'!$B:$B,'S1. USITC Imports'!H:H) -> 320.388 | I51: =_xlfn.XLOOKUP(_xlfn.CONCAT(_xlfn.TEXTSPLIT($D51,".")), 'S1. USITC Imports'!$B:$B,'S1. USITC Imports'!$J:$J)*_xlfn.XLOOKUP(_xlfn.CONCAT(_xlfn.TEXTSPLIT($D51,".")), 'S1. USITC Imports'!$B:$B,'S1. USITC Imports'!I:I) -> 270.188
B52: (1) Source: USITC DataWeb, Imports for Consumption
...

Sheet B9. HF
B2: Hydrofluoric Acid
B3: (quantities are representative of quantified form listed below, unless otherwise specified)
B5: Byproduct Information
B6: Chemical Formula of Quantified Form: | C6: HF
B7: 8-Digit USITC HTS Number: | C7: 2811.11.00
B8: Demand Data Market Specificity: | C8: Byproduct
B9: Demand Data Resolution: | C9: Domestic
B13: Major End-Use Markets1
B14: Assigned End-Use Category | C14: End-Use | D14: Demand (kt) | E14: % of Demand | G14: "Glass etching" was assigned to Semiconductor Manufacturing, based on reports from USGS that hydrofluoric acid is essential in cleaning and etching process during semiconductor manufacturing.1 End-uses with a market share <5% are consolidated into the "Other" category.
B15: Organic Chemical Manufacturing | C15: Fluorocarbon | D15: – | E15: 0.56
B16: Organic Chemical Manufacturing | C16: Fluorinated derivatives | D16: – | E16: 0.18333333
B17: Steel Pickling | C17: Metal pickling | D17: – | E17: 0.11388889
B18: Semiconductor Manufacturing | C18: Glass etching | D18: – | E18: 0.06
B19: Other | C19: Oil refining | D19: – | E19: 0.04
B20: Other | C20: Others | D20: – | E20: 0.047222222
B21: (1) Source: Grand View Research, Hydrofluoric Acid Market 2022-2030 | G21: (1) Source: USGS Mineral Commodity Summaries 2026, Fluorspar
B25: Domestic Demand
B26: Calculation Schema: | C26: Trade Balance Estimate
B27: Description | C27: Units | D27: 2021 | E27: 2022 | F27: 2023 | G27: 2024 | H27: 2025
B28: Domestic Production1 | C28: kt | D28: =D47 -> 200.3803 | E28: =E47 -> 229.59175 | F28: =F47 -> 193.71804 | G28: =G47 -> 190.64315 | H28: =H47 -> 184.49337
B29: Imports for Consumption2 | C29: kt | D29: =E57 -> 103.27172 | E29: =F57 -> 99.439092 | F29: =G57 -> 86.756697 | G29: =H57 -> 68.949172 | H29: =I57 -> 76.05068
B30: Domestic Exports3 | C30: kt | D30: =E62 -> 16.608258 | E30: =F62 -> 9.8888 | F30: =G62 -> 10.460104 | G30: =H62 -> 13.948911 | H30: =I62 -> 12.203279
B31: Consumption, apparent4 | C31: kt | D31: =D28+D29-D30 -> 287.04376 | E31: =E28+E29-E30 -> 319.14204 | F31: =F28+F29-F30 -> 270.01463 | G31: =G28+G29-G30 -> 245.64341 | H31: =H28+H29-H30 -> 248.34077
B32: (1) See "Domestic Production" section below
B33: (2) See "Imports and Exports" section below
B34: (3) See "Imports and Exports" section below
B35: (4) Production + Imports – Exports
B37: Demand Calculations
B38: Domestic Production
B39: Domestic production of hydrofluoric acid is tracked by the U.S. EPA under the Toxic Substances Control Act. When calculating the total production volumes of hydrofluoric acid from the 2024 CDR dataset, however, we find that the disclosed production volumes (~2-6 kt in total, each year) represent only a small fraction of total U.S. hydrofluoric acid manufacturing capacity (200 kt),1 likely due to information withheld from the public CDR dataset as confidential business information (CBI). Instead, we calculate hydrofluoric acid production indirectly, as a function of acid-grade fluorspar consumption, which is used entirely for hydrofluoric acid manufacturing (see B5. CaF2). To generate a conservative estimate (erring towards overestimation to provide an upper bound of demand), we perform these calculations stoichiometrically, where a single molecule of fluorspar translates to 2 hydrofluoric acid molecules. We assume 100% purity in the fluorspar feedstock. These calculations yield production estimates well in line with approximate US production capacities, but likely slightly overestimate hydrofluoric acid production volumes.
B40: (1) Source: ATSDR Toxicological Profile for Fluorides, Hydrogen Fluoride, and Fluorine
B42: Domestic Production, Hydrofluoric Acid
B43: Description | C43: Units | D43: 2021 | E43: 2022 | F43: 2023 | G43: 2024 | H43: 2025
B44: Consumption, apparent, acid-grade fluorspar1 | C44: kt | D44: ='B5. CaF2'!D23 -> 391 | E44: ='B5. CaF2'!E23 -> 448 | F44: ='B5. CaF2'!F23 -> 378 | G44: ='B5. CaF2'!G23 -> 372 | H44: ='B5. CaF2'!H23 -> 360
B45: Consumption, estimated calcium, fluoride2 | C45: Mmol | D45: =D44/(78.075) -> 5.0080051 | E45: =E44/(78.075) -> 5.7380724 | F45: =F44/(78.075) -> 4.8414986 | G45: =G44/(78.075) -> 4.7646494 | H45: =H44/(78.075) -> 4.610951
B46: Production, estimated, hydrofluoric acid3 | C46: Mmol | D46: =2*D45 -> 10.01601 | E46: =2*E45 -> 11.476145 | F46: =2*F45 -> 9.6829971 | G46: =2*G45 -> 9.5292988 | H46: =2*H45 -> 9.221902
B47: Production, estimated, hydrofluoric acid4 | C47: kt | D47: =D46*20.006 -> 200.3803 | E47: =E46*20.006 -> 229.59175 | F47: =F46*20.006 -> 193.71804 | G47: =G46*20.006 -> 190.64315 | H47: =H46*20.006 -> 184.49337
B48: (1) See B5. CaF2
B49: (2) Converted from fluorspar consumption assuming 100% calcium fluoride purity and molecular weight of 78.075 kt/Mmol. Molecular weight obtained from Python molmass package.
B50: (3) Stoichiometric yield of hydrofluoric acid from 1 mol calcium fluoride (CaF2 + H2SO4 --> 2HF + CaSO4)
...

Sheet B10. K2O
B2: Potash
B3: (quantities are representative of quantified form listed below, unless otherwise specified)
B5: Byproduct Information
B6: Chemical Formula of Quantified Form: | C6: K2O
B7: USGS Mineral Commodity Summary Page: | C7: Potash
B8: Demand Data Market Specificity: | C8: Byproduct
B9: Demand Data Resolution: | C9: Domestic
B13: Major End-Use Markets1
B14: Assigned End-Use Category | C14: End-Use | D14: Demand (kt) | E14: % of Demand
B15: Potash Fertilizer Application | C15: Fertilizer industry | D15: – | E15: 0.85
B16: Miscellaneous Chemical Manufacturing | C16: Chemical and industrial applications | D16: – | E16: 0.15
B17: (1) Source: USGS Mineral Commodity Summaries 2026, Potash
B21: Domestic Demand
B22: Calculation Schema: | C22: Direct Report
B23: Description | C23: Units | D23: 2021 | E23: 2022 | F23: 2023 | G23: 2024 | H23: 2025
B24: Consumption, apparent1 | C24: kt | D24: 6900 | E24: 5100 | F24: 5900 | G24: 6200 | H24: 5900
B25: (1) Source: USGS Mineral Commodity Summaries 2026, Potash
B29: Pricing
B30: Description | C30: Units | D30: 2021 | E30: 2022 | F30: 2023 | G30: 2024 | H30: 2025
B31: Price, average, f.o.b. mine, all products1 | C31: $/t | D31: 1120 | E31: 1790 | F31: 1250 | G31: 1150 | H31: 1200
B32: (1) Source: USGS Mineral Commodity Summaries 2026, Potash

Sheet B11. Li
B2: Lithium
B3: (quantities are representative of quantified form listed below, unless otherwise specified)
B5: Byproduct Information
B6: Chemical Formula of Quantified Form: | C6: Li
B7: USGS Mineral Commodity Summary Page: | C7: Lithium
B8: Demand Data Market Specificity: | C8: Byproduct
B9: Demand Data Resolution: | C9: Domestic
B13: Major End-Use Markets1
B14: Assigned End-Use Category | C14: End-Use | D14: Demand (kt) | E14: % of Demand | G14: End-uses with a market share <5% are consolidated into the "Other" category.
B15: Lithium Battery Manufacturing | C15: Batteries | D15: – | E15: 0.88
B16: Other | C16: Ceramics and glass | D16: – | E16: 0.04
B17: Other | C17: Lubricating greases | D17: – | E17: 0.02
B18: Other | C18: Air treatment | D18: – | E18: 0.01
B19: Other | C19: Continuous casting mold flux powders | D19: – | E19: 0.01
B20: Other | C20: Medical | D20: – | E20: 0.01
B21: Other | C21: Other | D21: – | E21: 0.03
B22: (1) Source: USGS Mineral Commodity Summaries 2026, Lithium
B26: Domestic Demand
B27: Calculation Schema: | C27: Trade Balance Estimate
B28: To avoid disclosing proprietary information, USGS withholds lithium consumption and production estimates. Because there is currently only one commercial-scale lithium producer in the United States, domestic lithium consumption is heavily import reliant. Though USGS does not report precise net import reliance, they provide a lower bound (e.g. >50%) that can be used to conservatively estimate an upper bound on domestic lithium demand.
B30: Description | C30: Units | D30: 2021 | E30: 2022 | F30: 2023 | G30: 2024 | H30: 2025
B31: Imports for Consumption1 | C31: kt | D31: 2.64 | E31: 3.26 | F31: 3.39 | G31: 3.02 | H31: 3.8
B32: Domestic Exports1 | C32: kt | D32: 1.87 | E32: 2.44 | F32: 1.96 | G32: 1.69 | H32: 2
B33: Minimum net import reliance1,2 | C33: – | D33: 0.25 | E33: 0.25 | F33: 0.5 | G33: 0.5 | H33: 0.5
B34: Consumption, apparent3 | C34: kt | D34: =(D31-D32)/D33 -> 3.08 | E34: =(E31-E32)/E33 -> 3.28 | F34: =(F31-F32)/F33 -> 2.86 | G34: =(G31-G32)/G33 -> 2.66 | H34: =(H31-H32)/H33 -> 3.6
B35: (1) Source: USGS Mineral Commodity Summaries 2026, Lithium
B36: (2) Defined by USGS as imports – exports +/- adjustments for industry stock changes, as a percentage of consumption. We ignore industry stock changes for the purposes of these estimations.
B37: (3) (Imports – Exports)/Net Import Reliance
B41: Pricing
B42: Description | C42: Units | D42: 2021 | E42: 2022 | F42: 2023 | G42: 2024 | H42: 2025
B43: Price, annual average-real, battery-grade lithium carbonate1 | C43: $/t Li2CO3 | D43: 11700 | E43: 63700 | F43: 39000 | G43: 11800 | H43: 9000
B44: Price, annual average-real, battery-grade lithium carbonate, lithium content2 | C44: $/t | D44: =D43/(2*6.94/73.888955) -> 62283.917 | E44: =E43/(2*6.94/73.888955) -> 339101.33 | F44: =F43/(2*6.94/73.888955) -> 207613.06 | G44: =G43/(2*6.94/73.888955) -> 62816.259 | H44: =H43/(2*6.94/73.888955) -> 47910.706
B45: (1) Source: USGS Mineral Commodity Summaries 2026, Lithium
B46: (2) Calculated from molcular weight ratio Lithium and Lithium Carbonate

Sheet B12. MgCl2
B2: Magnesium Chloride
B3: (quantities are representative of quantified form listed below, unless otherwise specified)
B5: Byproduct Information
B6: Chemical Formula of Quantified Form: | C6: MgCl2
B7: USGS Mineral Commodity Summary Page: | C7: Magnesium Compounds
B8: Demand Data Market Specificity: | C8: Byproduct-Market
B9: Demand Data Resolution: | C9: State
B13: Major End-Use Markets1
B14: Assigned End-Use Category | C14: End-Use | D14: Demand (kt) | E14: % of Demand2
B15: Deicing and Dust Control | C15: Deicing and dust control | D15: – | E15: 1
B16: (1) Source: USGS Minerals Yearbook 2020, Magnesium Compounds
B20: State-Level Demand by End-Use
B21: The Clear Roads Research Program conducts an annual survey of road maintenance data from U.S. states, from which we can extract magnesium chloride use as road salts by state directly.1 Magnesium chloride use is reported for both dry salt (in tons) and brine (in gallons). To calculate total magnesium chloride use (in tons), we assume brines are 22% MgCl2 by weight and have a density of about 10 lbs/gallon (0.005 tons/gal).2,3 We then add dry tons and equivalent dry tons from brine together to get total magnesium chloride application in each state in each year.
B22: In cases where a state did not provide a survey response in a given year, the maximum value across all 10 years of avaialble survey data is used, resulting in a conservative estimate of magnesium chloride demand. For a few states in CONUS (FL, MS, NC), there is no available data for any year covered by the survey (2015-2025). Because all of these states are in the southern US, where typical temperatures are warmer, we assume they apply zero magnesium chloride for deicing and dust control.
B23: (1) Source: Clear Roads Annual Survey of State Winter Maintenance Data
B24: (2) Source: Texas Department of Transportation
B25: (3) Source: General References Physical Properties of Pure Substances
B27: Deicing and Dust Control1
B28: State | C28: Units | D28: 2021 | E28: 2022 | F28: 2023 | G28: 2024 | H28: 2025
B29: Alabama | C29: kt | D29: {=IF(ISNUMBER(J196),J196,MAX(IF(ISNUMBER($D196:$N196),$D196:$N196,0)))} -> 0 | E29: {=IF(ISNUMBER(K196),K196,MAX(IF(ISNUMBER($D196:$N196),$D196:$N196,0)))} -> 10.477987 | F29: {=IF(ISNUMBER(L196),L196,MAX(IF(ISNUMBER($D196:$N196),$D196:$N196,0)))} -> 10.477987 | G29: {=IF(ISNUMBER(M196),M196,MAX(IF(ISNUMBER($D196:$N196),$D196:$N196,0)))} -> 10.477987 | H29: {=IF(ISNUMBER(N196),N196,MAX(IF(ISNUMBER($D196:$N196),$D196:$N196,0)))} -> 10.477987
B30: Alaska | C30: kt | D30: {=IF(ISNUMBER(J197),J197,MAX(IF(ISNUMBER($D197:$N197),$D197:$N197,0)))} -> 13616.847 | E30: {=IF(ISNUMBER(K197),K197,MAX(IF(ISNUMBER($D197:$N197),$D197:$N197,0)))} -> 13616.847 | F30: {=IF(ISNUMBER(L197),L197,MAX(IF(ISNUMBER($D197:$N197),$D197:$N197,0)))} -> 13616.847 | G30: {=IF(ISNUMBER(M197),M197,MAX(IF(ISNUMBER($D197:$N197),$D197:$N197,0)))} -> 13616.847 | H30: {=IF(ISNUMBER(N197),N197,MAX(IF(ISNUMBER($D197:$N197),$D197:$N197,0)))} -> 27.941298
B31: Arizona | C31: kt | D31: {=IF(ISNUMBER(J198),J198,MAX(IF(ISNUMBER($D198:$N198),$D198:$N198,0)))} -> 13.970649 | E31: {=IF(ISNUMBER(K198),K198,MAX(IF(ISNUMBER($D198:$N198),$D198:$N198,0)))} -> 223.47949 | F31: {=IF(ISNUMBER(L198),L198,MAX(IF(ISNUMBER($D198:$N198),$D198:$N198,0)))} -> 469.01465 | G31: {=IF(ISNUMBER(M198),M198,MAX(IF(ISNUMBER($D198:$N198),$D198:$N198,0)))} -> 295.28863 | H31: {=IF(ISNUMBER(N198),N198,MAX(IF(ISNUMBER($D198:$N198),$D198:$N198,0)))} -> 149.30342
B32: Arkansas | C32: kt | D32: {=IF(ISNUMBER(J199),J199,MAX(IF(ISNUMBER($D199:$N199),$D199:$N199,0)))} -> 14.669181 | E32: {=IF(ISNUMBER(K199),K199,MAX(IF(ISNUMBER($D199:$N199),$D199:$N199,0)))} -> 14.669181 | F32: {=IF(ISNUMBER(L199),L199,MAX(IF(ISNUMBER($D199:$N199),$D199:$N199,0)))} -> 14.669181 | G32: {=IF(ISNUMBER(M199),M199,MAX(IF(ISNUMBER($D199:$N199),$D199:$N199,0)))} -> 14.669181 | H32: {=IF(ISNUMBER(N199),N199,MAX(IF(ISNUMBER($D199:$N199),$D199:$N199,0)))} -> 14.669181
B33: California | C33: kt | D33: {=IF(ISNUMBER(J200),J200,MAX(IF(ISNUMBER($D200:$N200),$D200:$N200,0)))} -> 18235.326 | E33: {=IF(ISNUMBER(K200),K200,MAX(IF(ISNUMBER($D200:$N200),$D200:$N200,0)))} -> 18235.326 | F33: {=IF(ISNUMBER(L200),L200,MAX(IF(ISNUMBER($D200:$N200),$D200:$N200,0)))} -> 0 | G33: {=IF(ISNUMBER(M200),M200,MAX(IF(ISNUMBER($D200:$N200),$D200:$N200,0)))} -> 0 | H33: {=IF(ISNUMBER(N200),N200,MAX(IF(ISNUMBER($D200:$N200),$D200:$N200,0)))} -> 0
B34: Colorado | C34: kt | D34: {=IF(ISNUMBER(J201),J201,MAX(IF(ISNUMBER($D201:$N201),$D201:$N201,0)))} -> 12207.962 | E34: {=IF(ISNUMBER(K201),K201,MAX(IF(ISNUMBER($D201:$N201),$D201:$N201,0)))} -> 10165.646 | F34: {=IF(ISNUMBER(L201),L201,MAX(IF(ISNUMBER($D201:$N201),$D201:$N201,0)))} -> 11718.856 | G34: {=IF(ISNUMBER(M201),M201,MAX(IF(ISNUMBER($D201:$N201),$D201:$N201,0)))} -> 8605.357 | H34: {=IF(ISNUMBER(N201),N201,MAX(IF(ISNUMBER($D201:$N201),$D201:$N201,0)))} -> 20641.306
B35: Connecticut | C35: kt | D35: {=IF(ISNUMBER(J202),J202,MAX(IF(ISNUMBER($D202:$N202),$D202:$N202,0)))} -> 945.20122 | E35: {=IF(ISNUMBER(K202),K202,MAX(IF(ISNUMBER($D202:$N202),$D202:$N202,0)))} -> 603.33745 | F35: {=IF(ISNUMBER(L202),L202,MAX(IF(ISNUMBER($D202:$N202),$D202:$N202,0)))} -> 184813.4 | G35: {=IF(ISNUMBER(M202),M202,MAX(IF(ISNUMBER($D202:$N202),$D202:$N202,0)))} -> 695.83911 | H35: {=IF(ISNUMBER(N202),N202,MAX(IF(ISNUMBER($D202:$N202),$D202:$N202,0)))} -> 682.53705
B36: Delaware | C36: kt | D36: {=IF(ISNUMBER(J203),J203,MAX(IF(ISNUMBER($D203:$N203),$D203:$N203,0)))} -> 0 | E36: {=IF(ISNUMBER(K203),K203,MAX(IF(ISNUMBER($D203:$N203),$D203:$N203,0)))} -> 0 | F36: {=IF(ISNUMBER(L203),L203,MAX(IF(ISNUMBER($D203:$N203),$D203:$N203,0)))} -> 0 | G36: {=IF(ISNUMBER(M203),M203,MAX(IF(ISNUMBER($D203:$N203),$D203:$N203,0)))} -> 0 | H36: {=IF(ISNUMBER(N203),N203,MAX(IF(ISNUMBER($D203:$N203),$D203:$N203,0)))} -> 0
B37: District of Columbia | C37: kt | D37: {=IF(ISNUMBER(J204),J204,MAX(IF(ISNUMBER($D204:$N204),$D204:$N204,0)))} -> 0 | E37: {=IF(ISNUMBER(K204),K204,MAX(IF(ISNUMBER($D204:$N204),$D204:$N204,0)))} -> 0 | F37: {=IF(ISNUMBER(L204),L204,MAX(IF(ISNUMBER($D204:$N204),$D204:$N204,0)))} -> 0 | G37: {=IF(ISNUMBER(M204),M204,MAX(IF(ISNUMBER($D204:$N204),$D204:$N204,0)))} -> 0 | H37: {=IF(ISNUMBER(N204),N204,MAX(IF(ISNUMBER($D204:$N204),$D204:$N204,0)))} -> 0
B38: Florida | C38: kt | D38: {=IF(ISNUMBER(J205),J205,MAX(IF(ISNUMBER($D205:$N205),$D205:$N205,0)))} -> 0 | E38: {=IF(ISNUMBER(K205),K205,MAX(IF(ISNUMBER($D205:$N205),$D205:$N205,0)))} -> 0 | F38: {=IF(ISNUMBER(L205),L205,MAX(IF(ISNUMBER($D205:$N205),$D205:$N205,0)))} -> 0 | G38: {=IF(ISNUMBER(M205),M205,MAX(IF(ISNUMBER($D205:$N205),$D205:$N205,0)))} -> 0 | H38: {=IF(ISNUMBER(N205),N205,MAX(IF(ISNUMBER($D205:$N205),$D205:$N205,0)))} -> 0
B39: Georgia | C39: kt | D39: {=IF(ISNUMBER(J206),J206,MAX(IF(ISNUMBER($D206:$N206),$D206:$N206,0)))} -> 0 | E39: {=IF(ISNUMBER(K206),K206,MAX(IF(ISNUMBER($D206:$N206),$D206:$N206,0)))} -> 0 | F39: {=IF(ISNUMBER(L206),L206,MAX(IF(ISNUMBER($D206:$N206),$D206:$N206,0)))} -> 0 | G39: {=IF(ISNUMBER(M206),M206,MAX(IF(ISNUMBER($D206:$N206),$D206:$N206,0)))} -> 0 | H39: {=IF(ISNUMBER(N206),N206,MAX(IF(ISNUMBER($D206:$N206),$D206:$N206,0)))} -> 0
B40: Hawaii | C40: kt | D40: {=IF(ISNUMBER(J207),J207,MAX(IF(ISNUMBER($D207:$N207),$D207:$N207,0)))} -> 0 | E40: {=IF(ISNUMBER(K207),K207,MAX(IF(ISNUMBER($D207:$N207),$D207:$N207,0)))} -> 0 | F40: {=IF(ISNUMBER(L207),L207,MAX(IF(ISNUMBER($D207:$N207),$D207:$N207,0)))} -> 0 | G40: {=IF(ISNUMBER(M207),M207,MAX(IF(ISNUMBER($D207:$N207),$D207:$N207,0)))} -> 0 | H40: {=IF(ISNUMBER(N207),N207,MAX(IF(ISNUMBER($D207:$N207),$D207:$N207,0)))} -> 0
... B79: Wyoming | C79: kt | D79: {=IF(ISNUMBER(J246),J246,MAX(IF(ISNUMBER($D246:$N246),$D246:$N246,0)))} -> 3847.0098 | E79: {=IF(ISNUMBER(K246),K246,MAX(IF(ISNUMBER($D246:$N246),$D246:$N246,0)))} -> 54.862739 | F79: {=IF(ISNUMBER(L246),L246,MAX(IF(ISNUMBER($D246:$N246),$D246:$N246,0)))} -> 45.271888 | G79: {=IF(ISNUMBER(M246),M246,MAX(IF(ISNUMBER($D246:$N246),$D246:$N246,0)))} -> 45.830714 | H79: {=IF(ISNUMBER(N246),N246,MAX(IF(ISNUMBER($D246:$N246),$D246:$N246,0)))} -> 150.72135
B80: Total Withheld | C80: kt | D80: 0 | E80: 0 | F80: 0 | G80: 0 | H80: 0
B81: (1) Taken directly from Total Magnesium Chloride Applied table below, if available. Where no data is available, maximum across 10 years of data is assumed. Where no data is available for entire time period, 0 is assumed.
B83: Demand Calculations
B84: Dry Magnesium Chloride Applied
B85: State | C85: Units | D85: 2015 | E85: 2016 | F85: 2017 | G85: 2018 | H85: 2019 | I85: 2020 | J85: 2021 | K85: 2022 | L85: 2023 | M85: 2024 | N85: 2025
B86: Alabama | C86: tons | E86: 0 | F86: 0 | G86: 0 | H86: 11 | I86: 5 | J86: 0
B87: Alaska | C87: tons | E87: 0 | G87: 0 | M87: 15010 | N87: 0
B88: Arizona | C88: tons | D88: 0 | E88: 0 | H88: 0 | J88: 0 | L88: 0 | M88: 0 | N88: 1
...

Sheet B13. Mg(OH)2
B2: Magnesium Hydroxide
B3: (quantities are representative of quantified form listed below, unless otherwise specified)
B5: Byproduct Information
B6: Chemical Formula of Quantified Form: | C6: Mg(OH)2
B7: USGS Mineral Commodity Summary Page: | C7: Magnesium Compounds
B8: Demand Data Market Specificity: | C8: Byproduct
B9: Demand Data Resolution: | C9: Domestic
B13: Major End-Use Markets1
B14: Assigned End-Use Category | C14: End-Use | D14: Demand (kt) | E14: % of Demand | G14: Major domestic end uses for magnesium hydroxide were quantified by market share in USGS Minerals Yearbook 2020, Magnesium Compounds. This report further specifies magnesium hydroxide's primary use in water treatment as largely for treatment of wastewater and industrial effluent, so we categorize it under "Wastewater Treatment".
B15: Wastewater Treatment | C15: Water treatment | D15: – | E15: 0.8
B16: Miscellaneous Chemical Manufacturing | C16: Chemical intermediates | D16: – | E16: 0.11
B17: Other | C17: Other | D17: – | E17: 0.09
B18: (1) Source: USGS Minerals Yearbook 2020, Magnesium Compounds
B22: Domestic Demand
B23: Calculation Schema: | C23: Trade Balance Estimate
B24: Description | C24: Units | D24: 2021 | E24: 2022 | F24: 2023 | G24: 2024 | H24: 2025
B25: Domestic Production1 | C25: kt | D25: =D42 -> 188 | E25: =E42 -> 197 | F25: =F42 -> 173 | G25: =G42 -> 200 | H25: =H42 -> 200
B26: Imports for Consumption2 | C26: kt | D26: =E50 -> 12.765202 | E26: =F50 -> 13.075305 | F26: =G50 -> 9.980971 | G26: =H50 -> 11.150462 | H26: =I50 -> 13.101851
B27: Domestic Exports3 | C27: kt | D27: =E55 -> 17.71021 | E27: =F55 -> 16.046904 | F27: =G55 -> 14.518258 | G27: =H55 -> 17.811352 | H27: =I55 -> 17.483064
B28: Consumption, apparent4 | C28: kt | D28: =D25+D26-D27 -> 183.05499 | E28: =E25+E26-E27 -> 194.0284 | F28: =F25+F26-F27 -> 168.46271 | G28: =G25+G26-G27 -> 193.33911 | H28: =H25+H26-H27 -> 195.61879
B29: (1) See "Domestic Production" section below
B30: (2) See "Imports and Exports" section below
B31: (3) See "Imports and Exports" section below
B32: (4) Production + Imports – Exports
B34: Demand Calculations
B35: Domestic Production
B36: Reported volumes of magnesium hydroxide production are available from USGS for the years 2021-2023, so we adopt these values directly. With no production data yet available for 2024-2025, we approximate magnesium hydroxide production in these years based on production and trade balance data from 2021-2023. Throughout this time period, we see that production, imports for consumption, and exports for consumption remain quite stable, so we assume that there are no significant changes in magnesium hydroxide production in the two years to follow. To reflect this stability while erring on the side of overestimation to ensure we obtain a reasonable upper bound on demand, we round estimated production 200 kt for both years.
B38: Domestic Production, Magnesium Hydroxide
B39: Description | C39: Units | D39: 2021 | E39: 2022 | F39: 2023 | G39: 2024 | H39: 2025
B40: Reported domestic production1 | C40: kt | D40: 188 | E40: 197 | F40: 173 | G40: – | H40: –
B41: Estimated domestic production2 | C41: kt | D41: – | E41: – | F41: – | G41: 200 | H41: 200
B42: Assumed domestic production | C42: kt | D42: =D40 -> 188 | E42: =E40 -> 197 | F42: =F40 -> 173 | G42: =G41 -> 200 | H42: =H41 -> 200
B43: (1) Source: USGS Minerals Yearbook 2023, Magnesium Compounds
B44: (2) Conservative estimate based on previous years' production volumes
B46: Imports and Exports
B48: Imports for Consumption, Magnesium Hydroxide
B49: Product Name | C49: Units | D49: HTS Code | E49: 2021 | F49: 2022 | G49: 2023 | H49: 2024 | I49: 2025
B50: Magnesium hydroxide and peroxide1 | C50: kt | D50: 2816.10.0000 | E50: =_xlfn.XLOOKUP(_xlfn.CONCAT(_xlfn.TEXTSPLIT($D50,".")), 'S1. USITC Imports'!$B:$B,'S1. USITC Imports'!$J:$J)*_xlfn.XLOOKUP(_xlfn.CONCAT(_xlfn.TEXTSPLIT($D50,".")), 'S1. USITC Imports'!$B:$B,'S1. USITC Imports'!E:E) -> 12.765202 | F50: =_xlfn.XLOOKUP(_xlfn.CONCAT(_xlfn.TEXTSPLIT($D50,".")), 'S1. USITC Imports'!$B:$B,'S1. USITC Imports'!$J:$J)*_xlfn.XLOOKUP(_xlfn.CONCAT(_xlfn.TEXTSPLIT($D50,".")), 'S1. USITC Imports'!$B:$B,'S1. USITC Imports'!F:F) -> 13.075305 | G50: =_xlfn.XLOOKUP(_xlfn.CONCAT(_xlfn.TEXTSPLIT($D50,".")), 'S1. USITC Imports'!$B:$B,'S1. USITC Imports'!$J:$J)*_xlfn.XLOOKUP(_xlfn.CONCAT(_xlfn.TEXTSPLIT($D50,".")), 'S1. USITC Imports'!$B:$B,'S1. USITC Imports'!G:G) -> 9.980971 | H50: =_xlfn.XLOOKUP(_xlfn.CONCAT(_xlfn.TEXTSPLIT($D50,".")), 'S1. USITC Imports'!$B:$B,'S1. USITC Imports'!$J:$J)*_xlfn.XLOOKUP(_xlfn.CONCAT(_xlfn.TEXTSPLIT($D50,".")), 'S1. USITC Imports'!$B:$B,'S1. USITC Imports'!H:H) -> 11.150462 | I50: =_xlfn.XLOOKUP(_xlfn.CONCAT(_xlfn.TEXTSPLIT($D50,".")), 'S1. USITC Imports'!$B:$B,'S1. USITC Imports'!$J:$J)*_xlfn.XLOOKUP(_xlfn.CONCAT(_xlfn.TEXTSPLIT($D50,".")), 'S1. USITC Imports'!$B:$B,'S1. USITC Imports'!I:I) -> 13.101851
B51: (1) Source: USITC DataWeb, Imports for Consumption
B53: Domestic Exports, Magnesium Hydroxide
...

Sheet B14. MgSO4
B2: Magnesium Sulfate
B3: (quantities are representative of quantified form listed below, unless otherwise specified)
B5: Byproduct Information
B6: Chemical Formula of Quantified Form: | C6: MgSO4
B7: USGS Mineral Commodity Summary Page: | C7: Magnesium Compounds
B8: Demand Data Market Specificity: | C8: Byproduct
B9: Demand Data Resolution: | C9: Domestic
B13: Major End-Use Markets1
B14: Assigned End-Use Category | C14: End-Use | D14: Demand (kt) | E14: % of Demand | G14: Major domestic end uses for magnesium sulfate were most recently quantified by market share in USGS Minerals Yearbook 2020, Magnesium Compounds.
B15: Cosmetics and Personal Care Product Manufacturing | C15: Cosmetics and personal care | D15: – | E15: 0.48
B16: Miscellaneous Chemical Manufacturing | C16: Chemical intermediates | D16: – | E16: 0.22
B17: Pulp and Paper Manufacturing | C17: Pulp and paper | D17: – | E17: 0.12
B18: Miscellaneous Fertilizer Application | C18: Fertilizer | D18: – | E18: 0.1
B19: Other | C19: Other | D19: – | E19: 0.08
B20: (1) Source: USGS Minerals Yearbook 2020, Magnesium Compounds
B24: Domestic Demand
B25: Calculation Schema: | C25: Trade Balance Estimate
B26: Description | C26: Units | D26: 2021 | E26: 2022 | F26: 2023 | G26: 2024 | H26: 2025
B27: Domestic Production1 | C27: kt | D27: =I44 -> 81.9 | E27: =J44 -> 88.68 | F27: =K44 -> 95.46 | G27: =L44 -> 102.24 | H27: =M44 -> 109.02
B28: Imports for Consumption2 | C28: kt | D28: =E55 -> 48.172394 | E28: =F55 -> 39.152402 | F28: =G55 -> 27.625271 | G28: =H55 -> 46.59511 | H28: =I55 -> 44.332581
