Workbook

Sheet V1. Markets
B2: Major End-Use Markets
B3: Independent Benchmark Validation
B5: Bromine
B6: Assigned Major End-Use Categories (Tier 2)1
B7: Assigned End-Use Category | C7: End-Use | D7: Demand (kt) | E7: % of Demand
B8: Miscellaneous Chemical Manufacturing | C8: Flame retardant | D8: 483000 | E8: 0.5894557
B9: Oil and Gas Drilling | C9: Drilling fluids | D9: 103500 | E9: 0.12631194
B10: Organic Chemical Manufacturing | C10: Organic synthesis | D10: 86300 | E10: 0.10532097
B11: Pharmaceutical Manufacturing | C11: Pharmaceuticals | D11: 77600 | E11: 0.094703442
B12: Industrial Water Treatment | C12: Water treatment | D12: 69000 | E12: 0.084207957
B13: (1) Source: Ullmann's Encyclopedia for Industrial Chemistry, Bromine
B15: Independent Benchmark (Tier 3)1
B16: Assigned End-Use Category | C16: End-Use | D16: Revenue (Million USD) | E16: % of Demand
B17: Other | C17: Butyl Rubber | D17: 7.9 | E17: =D17/SUM($D$17:$D$27) -> 0.0089752329
B18: Miscellaneous Chemical Manufacturing | C18: Flame Retardants | D18: 369 | E18: =D18/SUM($D$17:$D$27) -> 0.4192229
B19: Other | C19: Hydrogen Bromide Flow Batteries | D19: 25.1 | E19: =D19/SUM($D$17:$D$27) -> 0.028516246
B20: Other | C20: Mercury Emission Control | D20: 33.8 | E20: =D20/SUM($D$17:$D$27) -> 0.038400364
B21: Oil and Gas Drilling | C21: Oil & Gas Drilling | D21: 250.2 | E21: =D21/SUM($D$17:$D$27) -> 0.28425358
B22: Other | C22: Other Applications | D22: 9 | E22: =D22/SUM($D$17:$D$27) -> 0.010224949
B23: Other | C23: Pesticides | D23: 25.5 | E23: =D23/SUM($D$17:$D$27) -> 0.028970688
B24: Other | C24: Pharmaceutical | D24: 17.2 | E24: =D24/SUM($D$17:$D$27) -> 0.019541013
B25: Other | C25: Plasma Etching | D25: 12.5 | E25: =D25/SUM($D$17:$D$27) -> 0.014201318
B26: Miscellaneous Chemical Manufacturing | C26: PTA Synthesis | D26: 80.7 | E26: =D26/SUM($D$17:$D$27) -> 0.091683708
B27: Industrial Water Treatment | C27: Water Treatment & Biocides | D27: 49.3 | E27: =D27/SUM($D$17:$D$27) -> 0.056009998
B28: (1) Source: Markets and Markets, US Bromine Market (2025-2030)
B32: Hydrofluoric Acid
B33: Assigned Major End-Use Categories (Tier 3)1
B34: Assigned End-Use Category | C34: End-Use | D34: Demand (kt) | E34: % of Demand
B35: Organic Chemical Manufacturing | C35: Fluorocarbon | D35: – | E35: 0.56
B36: Organic Chemical Manufacturing | C36: Fluorinated derivatives | D36: – | E36: 0.18333333
B37: Steel Pickling | C37: Metal pickling | D37: – | E37: 0.11388889
B38: Semiconductor Manufacturing | C38: Glass etching | D38: – | E38: 0.06
B39: Other | C39: Oil refining | D39: – | E39: 0.04
B40: Other | C40: Others | D40: – | E40: 0.047222222
B41: (1) Source: Grand View Research, Hydrofluoric Acid Market 2022-2030
B43: Independent Benchmark (Tier 3)1
B44: Assigned End-Use Category | C44: End-Use | D44: Revenue (Million USD) | E44: % of Demand
B45: Semiconductor Manufacturing | C45: Glass Etching & Cleaning | D45: 37.8 | E45: =D45/SUM($D$45:$D$51) -> 0.050861141
B46: Steel Pickling | C46: Metal Pickling | D46: 52.1 | E46: =D46/SUM($D$45:$D$51) -> 0.07010226
B47: Other | C47: Oil Refining | D47: 33.7 | E47: =D47/SUM($D$45:$D$51) -> 0.045344456
...

Sheet V2. Demand
B2: Domestic Byproduct Demand
B3: Independent Benchmark Validation
B5: Byproduct | C5: Assigned Tier | D5: Benchmark Demand (kt) | E5: Notes | F5: Source
B6: B | C6: 3 | D6: 580 | E6: represents borate consumption in North America (2024) | F6: Market Reports World, Borates Market Size, Share, Growth, and Industry Analysis, By Type (Borax, Boric Acid, Ulexite), By Application (Glass & Ceramics, Agriculture, Detergents), Regional Insights and Forecast to 2033
B7: BaSO4 | C7: 3 | D7: 2000 | E7: represents barite consumption for oil and gas industry in North America (2025) | F7: Market Reports World, Barite Products Market Size, Share, Growth, and Industry Analysis, By Type (Up to Grade 3.9, Grade 4.0, Grade 4.1, Grade 4.2, Grade 4.3, Grade above 4.3), By Application (Drilling Industry (Rig), Medical Industry, Rubber & Plastics,
B8: Br | C8: 3 | D8: 275 | E8: represents US consumption of bromine when it was last reported in 2006 | F8: USGS Mineral Commodity Summaries 2010, Bromine
B9: Ca(OH)2 | C9: 2 | D9: 2470 | E9: represents total hydrated lime sold or used by producers (2023) | F9: USGS Minerals Yearbook 2023, Lime
B10: HCl | C10: 3 | D10: 1458 | E10: represents US consumption of hydrochloric acid (2019) | F10: EPA Water Treatment Chemical Supply Chain Profile, Hydrochloric Acid
B11: HF | C11: 3 | D11: 320 | E11: represnts US consumption of liquid anhydrous hydrogen fluoride (2024) | F11: Market Growth Reports, Liquid Anhydrous Hydrogen Fluoride Market Report is Segmented by Types (99.99 AHF, 99.90 AHF, 99.70 AHF), Application (Chemical Industry, Mining & Metallurgical, Etching, Pharmaceuticals, Others), and Geography (North America, Europ
B12: Li | C12: 3 | D12: 3.75 | E12: represents lithium content of reported US lithium carbonate equivalent consumption in 2024 | F12: S&P Global, America's Lithium Market Navigates Slow Progress Amid Opportunities
B13: Mg(OH)2 | C13: 3 | D13: 190 | E13: represents apparent consumption of magnesium hydroxide (2020) | F13: USGS Minerals Yearbook 2020, Magnesium Compounds
B14: MgSO4 | C14: 3 | D14: 72.9 | E14: represents magnesium sulfate shipped by producers (2020) | F14: USGS Minerals Yearbook 2020, Magnesium Compounds
B15: NaOH | C15: 3 | D15: 6000 | E15: represents US consumption of sodium hydroxide (2019) | F15: EPA Water Treatment Chemical Supply Chain Profile, Sodium Hydroxide
B16: P2O5 | C16: 2 | D16: 5700 | E16: represnts P2O5 content of phosphate rock sold or used by producers (2023) | F16: USGS Minerals Yearbook 2023, Phosphate Rock

Sheet V3. Disaggregation Proxies
B2: Disaggregation Proxies
B3: Cross-Tier Validation
B5: Calcium carbonate (CaCO3) for Cement Manufacturing is the only byproduct-market pair for which abundant state level use and disaggregation proxy data exists, so we use it for cross-tier validation of disaggregation proxies.
B7: Percent of Byproduct-Market Demand Attributable to Each District, by Tier1,2
B8: District | C8: Ground Truth | D8: Tier 1 | E8: Tier 2 | F8: Tier 3 | G8: Tier 4
B9: Maine and New York | C9: =IF(ISERROR(_xlfn.XLOOKUP(B9,$H$36:$H$54,$J$36:$J$54)/$J$55), "", (_xlfn.XLOOKUP(B9,$H$36:$H$54,$J$36:$J$54)/$J$55)) -> 0.023127273 | D9: =_xlfn.XLOOKUP(B9,$H$92:$H$110,$I$92:$I$110)/$I$111 -> 0.022233914 | E9: =_xlfn.XLOOKUP(B9,$H$121:$H$139,$I$121:$I$139)/$I$140 -> 0.021295164 | F9: =_xlfn.XLOOKUP(B9,$H$121:$H$139,$I$121:$I$139)/$I$140 -> 0.021295164 | G9: =_xlfn.XLOOKUP(B9,$H$247:$H$265,$I$247:$I$265)/$I$266 -> 0.04040404
B10: Pennsylvania | C10: =IF(ISERROR(_xlfn.XLOOKUP(B10,$H$36:$H$54,$J$36:$J$54)/$J$55), "", (_xlfn.XLOOKUP(B10,$H$36:$H$54,$J$36:$J$54)/$J$55)) -> 0.047181818 | D10: =_xlfn.XLOOKUP(B10,$H$92:$H$110,$I$92:$I$110)/$I$111 -> 0.039458334 | E10: =_xlfn.XLOOKUP(B10,$H$121:$H$139,$I$121:$I$139)/$I$140 -> 0.044032606 | F10: =_xlfn.XLOOKUP(B10,$H$121:$H$139,$I$121:$I$139)/$I$140 -> 0.044032606 | G10: =_xlfn.XLOOKUP(B10,$H$247:$H$265,$I$247:$I$265)/$I$266 -> 0.070707071
B11: Illinois | C11: =IF(ISERROR(_xlfn.XLOOKUP(B11,$H$36:$H$54,$J$36:$J$54)/$J$55), "", (_xlfn.XLOOKUP(B11,$H$36:$H$54,$J$36:$J$54)/$J$55)) | D11: =_xlfn.XLOOKUP(B11,$H$92:$H$110,$I$92:$I$110)/$I$111 -> 0.015200037 | E11: =_xlfn.XLOOKUP(B11,$H$121:$H$139,$I$121:$I$139)/$I$140 -> 0.017139801 | F11: =_xlfn.XLOOKUP(B11,$H$121:$H$139,$I$121:$I$139)/$I$140 -> 0.017139801 | G11: =_xlfn.XLOOKUP(B11,$H$247:$H$265,$I$247:$I$265)/$I$266 -> 0.03030303
B12: Indiana, Ohio | C12: =IF(ISERROR(_xlfn.XLOOKUP(B12,$H$36:$H$54,$J$36:$J$54)/$J$55), "", (_xlfn.XLOOKUP(B12,$H$36:$H$54,$J$36:$J$54)/$J$55)) -> 0.042363636 | D12: =_xlfn.XLOOKUP(B12,$H$92:$H$110,$I$92:$I$110)/$I$111 -> 0.043941716 | E12: =_xlfn.XLOOKUP(B12,$H$121:$H$139,$I$121:$I$139)/$I$140 -> 0.049296063 | F12: =_xlfn.XLOOKUP(B12,$H$121:$H$139,$I$121:$I$139)/$I$140 -> 0.049296063 | G12: =_xlfn.XLOOKUP(B12,$H$247:$H$265,$I$247:$I$265)/$I$266 -> 0.060606061
B13: Michigan | C13: =IF(ISERROR(_xlfn.XLOOKUP(B13,$H$36:$H$54,$J$36:$J$54)/$J$55), "", (_xlfn.XLOOKUP(B13,$H$36:$H$54,$J$36:$J$54)/$J$55)) | D13: =_xlfn.XLOOKUP(B13,$H$92:$H$110,$I$92:$I$110)/$I$111 -> 0.054646934 | E13: =_xlfn.XLOOKUP(B13,$H$121:$H$139,$I$121:$I$139)/$I$140 -> 0.047991302 | F13: =_xlfn.XLOOKUP(B13,$H$121:$H$139,$I$121:$I$139)/$I$140 -> 0.047991302 | G13: =_xlfn.XLOOKUP(B13,$H$247:$H$265,$I$247:$I$265)/$I$266 -> 0.03030303
B14: Iowa, Nebraska, South Dakota | C14: =IF(ISERROR(_xlfn.XLOOKUP(B14,$H$36:$H$54,$J$36:$J$54)/$J$55), "", (_xlfn.XLOOKUP(B14,$H$36:$H$54,$J$36:$J$54)/$J$55)) | D14: =_xlfn.XLOOKUP(B14,$H$92:$H$110,$I$92:$I$110)/$I$111 -> 0.041036668 | E14: =_xlfn.XLOOKUP(B14,$H$121:$H$139,$I$121:$I$139)/$I$140 -> 0.041990456 | F14: =_xlfn.XLOOKUP(B14,$H$121:$H$139,$I$121:$I$139)/$I$140 -> 0.041990456 | G14: =_xlfn.XLOOKUP(B14,$H$247:$H$265,$I$247:$I$265)/$I$266 -> 0.04040404
B15: Kansas | C15: =IF(ISERROR(_xlfn.XLOOKUP(B15,$H$36:$H$54,$J$36:$J$54)/$J$55), "", (_xlfn.XLOOKUP(B15,$H$36:$H$54,$J$36:$J$54)/$J$55)) | D15: =_xlfn.XLOOKUP(B15,$H$92:$H$110,$I$92:$I$110)/$I$111 -> 0.057323238 | E15: =_xlfn.XLOOKUP(B15,$H$121:$H$139,$I$121:$I$139)/$I$140 -> 0.033605517 | F15: =_xlfn.XLOOKUP(B15,$H$121:$H$139,$I$121:$I$139)/$I$140 -> 0.033605517 | G15: =_xlfn.XLOOKUP(B15,$H$247:$H$265,$I$247:$I$265)/$I$266 -> 0.060606061
B16: Missouri | C16: =IF(ISERROR(_xlfn.XLOOKUP(B16,$H$36:$H$54,$J$36:$J$54)/$J$55), "", (_xlfn.XLOOKUP(B16,$H$36:$H$54,$J$36:$J$54)/$J$55)) -> 0.10818182 | D16: =_xlfn.XLOOKUP(B16,$H$92:$H$110,$I$92:$I$110)/$I$111 -> 0.11277078 | E16: =_xlfn.XLOOKUP(B16,$H$121:$H$139,$I$121:$I$139)/$I$140 -> 0.10300249 | F16: =_xlfn.XLOOKUP(B16,$H$121:$H$139,$I$121:$I$139)/$I$140 -> 0.10300249 | G16: =_xlfn.XLOOKUP(B16,$H$247:$H$265,$I$247:$I$265)/$I$266 -> 0.050505051
B17: Florida | C17: =IF(ISERROR(_xlfn.XLOOKUP(B17,$H$36:$H$54,$J$36:$J$54)/$J$55), "", (_xlfn.XLOOKUP(B17,$H$36:$H$54,$J$36:$J$54)/$J$55)) -> 0.048818182 | D17: =_xlfn.XLOOKUP(B17,$H$92:$H$110,$I$92:$I$110)/$I$111 -> 0.072866391 | E17: =_xlfn.XLOOKUP(B17,$H$121:$H$139,$I$121:$I$139)/$I$140 -> 0.06336831 | F17: =_xlfn.XLOOKUP(B17,$H$121:$H$139,$I$121:$I$139)/$I$140 -> 0.06336831 | G17: =_xlfn.XLOOKUP(B17,$H$247:$H$265,$I$247:$I$265)/$I$266 -> 0.080808081
B18: Georgia, Maryland, Virginia, West Virginia | C18: =IF(ISERROR(_xlfn.XLOOKUP(B18,$H$36:$H$54,$J$36:$J$54)/$J$55), "", (_xlfn.XLOOKUP(B18,$H$36:$H$54,$J$36:$J$54)/$J$55)) | D18: =_xlfn.XLOOKUP(B18,$H$92:$H$110,$I$92:$I$110)/$I$111 -> 0.06862319 | E18: =_xlfn.XLOOKUP(B18,$H$121:$H$139,$I$121:$I$139)/$I$140 -> 0.065548173 | F18: =_xlfn.XLOOKUP(B18,$H$121:$H$139,$I$121:$I$139)/$I$140 -> 0.065548173 | G18: =_xlfn.XLOOKUP(B18,$H$247:$H$265,$I$247:$I$265)/$I$266 -> 0.060606061
B19: South Carolina | C19: =IF(ISERROR(_xlfn.XLOOKUP(B19,$H$36:$H$54,$J$36:$J$54)/$J$55), "", (_xlfn.XLOOKUP(B19,$H$36:$H$54,$J$36:$J$54)/$J$55)) -> 0.018727273 | D19: =_xlfn.XLOOKUP(B19,$H$92:$H$110,$I$92:$I$110)/$I$111 -> 0.033522428 | E19: =_xlfn.XLOOKUP(B19,$H$121:$H$139,$I$121:$I$139)/$I$140 -> 0.034855166 | F19: =_xlfn.XLOOKUP(B19,$H$121:$H$139,$I$121:$I$139)/$I$140 -> 0.034855166 | G19: =_xlfn.XLOOKUP(B19,$H$247:$H$265,$I$247:$I$265)/$I$266 -> 0.03030303
B20: Alabama, Kentucky, Tennessee | C20: =IF(ISERROR(_xlfn.XLOOKUP(B20,$H$36:$H$54,$J$36:$J$54)/$J$55), "", (_xlfn.XLOOKUP(B20,$H$36:$H$54,$J$36:$J$54)/$J$55)) | D20: =_xlfn.XLOOKUP(B20,$H$92:$H$110,$I$92:$I$110)/$I$111 -> 0.090273807 | E20: =_xlfn.XLOOKUP(B20,$H$121:$H$139,$I$121:$I$139)/$I$140 -> 0.093484702 | F20: =_xlfn.XLOOKUP(B20,$H$121:$H$139,$I$121:$I$139)/$I$140 -> 0.093484702 | G20: =_xlfn.XLOOKUP(B20,$H$247:$H$265,$I$247:$I$265)/$I$266 -> 0.080808081
... B27: Oregon and Washington | C27: =IF(ISERROR(_xlfn.XLOOKUP(B27,$H$36:$H$54,$J$36:$J$54)/$J$55), "", (_xlfn.XLOOKUP(B27,$H$36:$H$54,$J$36:$J$54)/$J$55)) | D27: =_xlfn.XLOOKUP(B27,$H$92:$H$110,$I$92:$I$110)/$I$111 -> 0.016675435 | E27: =_xlfn.XLOOKUP(B27,$H$121:$H$139,$I$121:$I$139)/$I$140 -> 0.014223674 | F27: =_xlfn.XLOOKUP(B27,$H$121:$H$139,$I$121:$I$139)/$I$140 -> 0.014223674 | G27: =_xlfn.XLOOKUP(B27,$H$247:$H$265,$I$247:$I$265)/$I$266 -> 0.04040404
B28: (1) Districts based on those in USGS Minerals Yearbook 2023, Cement. Districts with sub-state resolution (e.g. Texas, northern) are aggregated to the state level to ensure consistency in tier resolution
B29: (2) See sources of data for each tier below
B33: Ground Truth: State-Level Byproduct-Market Demand
B34: Limestone and Dolomite Sold or Used by Producers for Cement Manufacturing in 2023, by State1 | H34: Limestone and Dolomite Sold or Used by Producers for Cement Manufacturing in 2023, by District
B35: State Name | C35: Use (kt) | H35: District | I35: Complete1 | J35: Use (kt)
B36: Alabama | C36: 4660 | H36: Maine and New York | I36: {=AND(ISNUMBER(_xlfn.XLOOKUP(TRIM(_xlfn.TEXTSPLIT(SUBSTITUTE(H36," and ",","),",")),$B$36:$B$83,$C$36:$C$83)))} -> TRUE | J36: {=IF(I36,SUM(_xlfn.XLOOKUP(TRIM(_xlfn.TEXTSPLIT(SUBSTITUTE(H36," and ",","),",")),$B$36:$B$83,$C$36:$C$83)),"")} -> 2544
B37: Arizona | C37: W | H37: Pennsylvania | I37: {=AND(ISNUMBER(_xlfn.XLOOKUP(TRIM(_xlfn.TEXTSPLIT(SUBSTITUTE(H37," and ",","),",")),$B$36:$B$83,$C$36:$C$83)))} -> TRUE | J37: {=IF(I37,SUM(_xlfn.XLOOKUP(TRIM(_xlfn.TEXTSPLIT(SUBSTITUTE(H37," and ",","),",")),$B$36:$B$83,$C$36:$C$83)),"")} -> 5190
B38: Arkansas | C38: W | H38: Illinois | I38: {=AND(ISNUMBER(_xlfn.XLOOKUP(TRIM(_xlfn.TEXTSPLIT(SUBSTITUTE(H38," and ",","),",")),$B$36:$B$83,$C$36:$C$83)))} -> FALSE | J38: {=IF(I38,SUM(_xlfn.XLOOKUP(TRIM(_xlfn.TEXTSPLIT(SUBSTITUTE(H38," and ",","),",")),$B$36:$B$83,$C$36:$C$83)),"")}
B39: California | C39: 12300 | H39: Indiana, Ohio | I39: {=AND(ISNUMBER(_xlfn.XLOOKUP(TRIM(_xlfn.TEXTSPLIT(SUBSTITUTE(H39," and ",","),",")),$B$36:$B$83,$C$36:$C$83)))} -> TRUE | J39: {=IF(I39,SUM(_xlfn.XLOOKUP(TRIM(_xlfn.TEXTSPLIT(SUBSTITUTE(H39," and ",","),",")),$B$36:$B$83,$C$36:$C$83)),"")} -> 4660
B40: Colorado | C40: 3140 | H40: Michigan | I40: {=AND(ISNUMBER(_xlfn.XLOOKUP(TRIM(_xlfn.TEXTSPLIT(SUBSTITUTE(H40," and ",","),",")),$B$36:$B$83,$C$36:$C$83)))} -> FALSE | J40: {=IF(I40,SUM(_xlfn.XLOOKUP(TRIM(_xlfn.TEXTSPLIT(SUBSTITUTE(H40," and ",","),",")),$B$36:$B$83,$C$36:$C$83)),"")}
B41: Connecticut | C41: 0 | H41: Iowa, Nebraska, South Dakota | I41: {=AND(ISNUMBER(_xlfn.XLOOKUP(TRIM(_xlfn.TEXTSPLIT(SUBSTITUTE(H41," and ",","),",")),$B$36:$B$83,$C$36:$C$83)))} -> FALSE | J41: {=IF(I41,SUM(_xlfn.XLOOKUP(TRIM(_xlfn.TEXTSPLIT(SUBSTITUTE(H41," and ",","),",")),$B$36:$B$83,$C$36:$C$83)),"")}
B42: Delaware | C42: 0 | H42: Kansas | I42: {=AND(ISNUMBER(_xlfn.XLOOKUP(TRIM(_xlfn.TEXTSPLIT(SUBSTITUTE(H42," and ",","),",")),$B$36:$B$83,$C$36:$C$83)))} -> FALSE | J42: {=IF(I42,SUM(_xlfn.XLOOKUP(TRIM(_xlfn.TEXTSPLIT(SUBSTITUTE(H42," and ",","),",")),$B$36:$B$83,$C$36:$C$83)),"")}
B43: Florida | C43: 5370 | H43: Missouri | I43: {=AND(ISNUMBER(_xlfn.XLOOKUP(TRIM(_xlfn.TEXTSPLIT(SUBSTITUTE(H43," and ",","),",")),$B$36:$B$83,$C$36:$C$83)))} -> TRUE | J43: {=IF(I43,SUM(_xlfn.XLOOKUP(TRIM(_xlfn.TEXTSPLIT(SUBSTITUTE(H43," and ",","),",")),$B$36:$B$83,$C$36:$C$83)),"")} -> 11900
B44: Georgia | C44: 530 | H44: Florida | I44: {=AND(ISNUMBER(_xlfn.XLOOKUP(TRIM(_xlfn.TEXTSPLIT(SUBSTITUTE(H44," and ",","),",")),$B$36:$B$83,$C$36:$C$83)))} -> TRUE | J44: {=IF(I44,SUM(_xlfn.XLOOKUP(TRIM(_xlfn.TEXTSPLIT(SUBSTITUTE(H44," and ",","),",")),$B$36:$B$83,$C$36:$C$83)),"")} -> 5370
B45: Idaho | C45: 0 | H45: Georgia, Maryland, Virginia, West Virginia | I45: {=AND(ISNUMBER(_xlfn.XLOOKUP(TRIM(_xlfn.TEXTSPLIT(SUBSTITUTE(H45," and ",","),",")),$B$36:$B$83,$C$36:$C$83)))} -> FALSE | J45: {=IF(I45,SUM(_xlfn.XLOOKUP(TRIM(_xlfn.TEXTSPLIT(SUBSTITUTE(H45," and ",","),",")),$B$36:$B$83,$C$36:$C$83)),"")}
B46: Illinois | C46: W | H46: South Carolina | I46: {=AND(ISNUMBER(_xlfn.XLOOKUP(TRIM(_xlfn.TEXTSPLIT(SUBSTITUTE(H46," and ",","),",")),$B$36:$B$83,$C$36:$C$83)))} -> TRUE | J46: {=IF(I46,SUM(_xlfn.XLOOKUP(TRIM(_xlfn.TEXTSPLIT(SUBSTITUTE(H46," and ",","),",")),$B$36:$B$83,$C$36:$C$83)),"")} -> 2060
B47: Indiana | C47: 3520 | H47: Alabama, Kentucky, Tennessee | I47: {=AND(ISNUMBER(_xlfn.XLOOKUP(TRIM(_xlfn.TEXTSPLIT(SUBSTITUTE(H47," and ",","),",")),$B$36:$B$83,$C$36:$C$83)))} -> FALSE | J47: {=IF(I47,SUM(_xlfn.XLOOKUP(TRIM(_xlfn.TEXTSPLIT(SUBSTITUTE(H47," and ",","),",")),$B$36:$B$83,$C$36:$C$83)),"")}
B48: Iowa | C48: 2150 | H48: Arkansas and Oklahoma | I48: {=AND(ISNUMBER(_xlfn.XLOOKUP(TRIM(_xlfn.TEXTSPLIT(SUBSTITUTE(H48," and ",","),",")),$B$36:$B$83,$C$36:$C$83)))} -> FALSE | J48: {=IF(I48,SUM(_xlfn.XLOOKUP(TRIM(_xlfn.TEXTSPLIT(SUBSTITUTE(H48," and ",","),",")),$B$36:$B$83,$C$36:$C$83)),"")}
B49: Kansas | C49: W | H49: Texas | I49: {=AND(ISNUMBER(_xlfn.XLOOKUP(TRIM(_xlfn.TEXTSPLIT(SUBSTITUTE(H49," and ",","),",")),$B$36:$B$83,$C$36:$C$83)))} -> TRUE | J49: {=IF(I49,SUM(_xlfn.XLOOKUP(TRIM(_xlfn.TEXTSPLIT(SUBSTITUTE(H49," and ",","),",")),$B$36:$B$83,$C$36:$C$83)),"")} -> 20300
B50: Kentucky | C50: 1770 | H50: Arizona and New Mexico | I50: {=AND(ISNUMBER(_xlfn.XLOOKUP(TRIM(_xlfn.TEXTSPLIT(SUBSTITUTE(H50," and ",","),",")),$B$36:$B$83,$C$36:$C$83)))} -> FALSE | J50: {=IF(I50,SUM(_xlfn.XLOOKUP(TRIM(_xlfn.TEXTSPLIT(SUBSTITUTE(H50," and ",","),",")),$B$36:$B$83,$C$36:$C$83)),"")}
B51: Louisiana | C51: 0 | H51: Colorado and Wyoming | I51: {=AND(ISNUMBER(_xlfn.XLOOKUP(TRIM(_xlfn.TEXTSPLIT(SUBSTITUTE(H51," and ",","),",")),$B$36:$B$83,$C$36:$C$83)))} -> FALSE | J51: {=IF(I51,SUM(_xlfn.XLOOKUP(TRIM(_xlfn.TEXTSPLIT(SUBSTITUTE(H51," and ",","),",")),$B$36:$B$83,$C$36:$C$83)),"")}
B52: Maine | C52: 394 | H52: Montana, Nevada, Utah | I52: {=AND(ISNUMBER(_xlfn.XLOOKUP(TRIM(_xlfn.TEXTSPLIT(SUBSTITUTE(H52," and ",","),",")),$B$36:$B$83,$C$36:$C$83)))} -> FALSE | J52: {=IF(I52,SUM(_xlfn.XLOOKUP(TRIM(_xlfn.TEXTSPLIT(SUBSTITUTE(H52," and ",","),",")),$B$36:$B$83,$C$36:$C$83)),"")}
...

Sheet X1. Markets
A1: byproduct | B1: end_use_category | C1: Assigned | D1: Benchmark
A2: Br | B2: {=_xlfn.UNIQUE(_xlfn.VSTACK('V1. Markets'!B8:B12,'V1. Markets'!B17:B27))} -> Miscellaneous Chemical Manufacturing | C2: =SUMIF('V1. Markets'!$B$8:$B$12,'X1. Markets'!B2,'V1. Markets'!$E$8:$E$12) -> 0.5894557 | D2: =SUMIF('V1. Markets'!$B$17:$B$27,'X1. Markets'!B2,'V1. Markets'!$E$17:$E$27) -> 0.51090661
A3: Br | B3: Oil and Gas Drilling | C3: =SUMIF('V1. Markets'!$B$8:$B$12,'X1. Markets'!B3,'V1. Markets'!$E$8:$E$12) -> 0.12631194 | D3: =SUMIF('V1. Markets'!$B$17:$B$27,'X1. Markets'!B3,'V1. Markets'!$E$17:$E$27) -> 0.28425358
A4: Br | B4: Organic Chemical Manufacturing | C4: =SUMIF('V1. Markets'!$B$8:$B$12,'X1. Markets'!B4,'V1. Markets'!$E$8:$E$12) -> 0.10532097 | D4: =SUMIF('V1. Markets'!$B$17:$B$27,'X1. Markets'!B4,'V1. Markets'!$E$17:$E$27) -> 0
A5: Br | B5: Pharmaceutical Manufacturing | C5: =SUMIF('V1. Markets'!$B$8:$B$12,'X1. Markets'!B5,'V1. Markets'!$E$8:$E$12) -> 0.094703442 | D5: =SUMIF('V1. Markets'!$B$17:$B$27,'X1. Markets'!B5,'V1. Markets'!$E$17:$E$27) -> 0
A6: Br | B6: Industrial Water Treatment | C6: =SUMIF('V1. Markets'!$B$8:$B$12,'X1. Markets'!B6,'V1. Markets'!$E$8:$E$12) -> 0.084207957 | D6: =SUMIF('V1. Markets'!$B$17:$B$27,'X1. Markets'!B6,'V1. Markets'!$E$17:$E$27) -> 0.056009998
A7: Br | B7: Other | C7: =SUMIF('V1. Markets'!$B$8:$B$12,'X1. Markets'!B7,'V1. Markets'!$E$8:$E$12) -> 0 | D7: =SUMIF('V1. Markets'!$B$17:$B$27,'X1. Markets'!B7,'V1. Markets'!$E$17:$E$27) -> 0.14882981
A8: HF | B8: {=_xlfn.UNIQUE(_xlfn.VSTACK('V1. Markets'!B35:B40,'V1. Markets'!B45:B51))} -> Organic Chemical Manufacturing | C8: =SUMIF('V1. Markets'!$B$35:$B$40,'X1. Markets'!B8,'V1. Markets'!$E$35:$E$40) -> 0.74333333 | D8: =SUMIF('V1. Markets'!$B$45:$B$51,'X1. Markets'!B8,'V1. Markets'!$E$45:$E$51) -> 0.77758342
A9: HF | B9: Steel Pickling | C9: =SUMIF('V1. Markets'!$B$35:$B$40,'X1. Markets'!B9,'V1. Markets'!$E$35:$E$40) -> 0.11388889 | D9: =SUMIF('V1. Markets'!$B$45:$B$51,'X1. Markets'!B9,'V1. Markets'!$E$45:$E$51) -> 0.07010226
A10: HF | B10: Semiconductor Manufacturing | C10: =SUMIF('V1. Markets'!$B$35:$B$40,'X1. Markets'!B10,'V1. Markets'!$E$35:$E$40) -> 0.06 | D10: =SUMIF('V1. Markets'!$B$45:$B$51,'X1. Markets'!B10,'V1. Markets'!$E$45:$E$51) -> 0.050861141
A11: HF | B11: Other | C11: =SUMIF('V1. Markets'!$B$35:$B$40,'X1. Markets'!B11,'V1. Markets'!$E$35:$E$40) -> 0.087222222 | D11: =SUMIF('V1. Markets'!$B$45:$B$51,'X1. Markets'!B11,'V1. Markets'!$E$45:$E$51) -> 0.10145318

Sheet X2. Demand
A1: byproduct | B1: benchmark_demand_kt
A2: {=_xlfn.UNIQUE('V2. Demand'!B6:B16)} -> B | B2: =_xlfn.XLOOKUP($A2,'V2. Demand'!$B:$B,'V2. Demand'!D:D) -> 580
A3: BaSO4 | B3: =_xlfn.XLOOKUP($A3,'V2. Demand'!$B:$B,'V2. Demand'!D:D) -> 2000
A4: Br | B4: =_xlfn.XLOOKUP($A4,'V2. Demand'!$B:$B,'V2. Demand'!D:D) -> 275
A5: Ca(OH)2 | B5: =_xlfn.XLOOKUP($A5,'V2. Demand'!$B:$B,'V2. Demand'!D:D) -> 2470
A6: HCl | B6: =_xlfn.XLOOKUP($A6,'V2. Demand'!$B:$B,'V2. Demand'!D:D) -> 1458
A7: HF | B7: =_xlfn.XLOOKUP($A7,'V2. Demand'!$B:$B,'V2. Demand'!D:D) -> 320
A8: Li | B8: =_xlfn.XLOOKUP($A8,'V2. Demand'!$B:$B,'V2. Demand'!D:D) -> 3.75
A9: Mg(OH)2 | B9: =_xlfn.XLOOKUP($A9,'V2. Demand'!$B:$B,'V2. Demand'!D:D) -> 190
A10: MgSO4 | B10: =_xlfn.XLOOKUP($A10,'V2. Demand'!$B:$B,'V2. Demand'!D:D) -> 72.9
A11: NaOH | B11: =_xlfn.XLOOKUP($A11,'V2. Demand'!$B:$B,'V2. Demand'!D:D) -> 6000
A12: P2O5 | B12: =_xlfn.XLOOKUP($A12,'V2. Demand'!$B:$B,'V2. Demand'!D:D) -> 5700

Sheet X3. Disaggregation Proxies
A1: {='V3. Disaggregation Proxies'!B8:G27} -> District | B1: Ground Truth | C1: Tier 1 | D1: Tier 2 | E1: Tier 3 | F1: Tier 4
A2: Maine and New York | B2: 0.023127273 | C2: 0.022233914 | D2: 0.021295164 | E2: 0.021295164 | F2: 0.04040404
A3: Pennsylvania | B3: 0.047181818 | C3: 0.039458334 | D3: 0.044032606 | E3: 0.044032606 | F3: 0.070707071
A4: Illinois | C4: 0.015200037 | D4: 0.017139801 | E4: 0.017139801 | F4: 0.03030303
A5: Indiana, Ohio | B5: 0.042363636 | C5: 0.043941716 | D5: 0.049296063 | E5: 0.049296063 | F5: 0.060606061
A6: Michigan | C6: 0.054646934 | D6: 0.047991302 | E6: 0.047991302 | F6: 0.03030303
A7: Iowa, Nebraska, South Dakota | C7: 0.041036668 | D7: 0.041990456 | E7: 0.041990456 | F7: 0.04040404
A8: Kansas | C8: 0.057323238 | D8: 0.033605517 | E8: 0.033605517 | F8: 0.060606061
A9: Missouri | B9: 0.10818182 | C9: 0.11277078 | D9: 0.10300249 | E9: 0.10300249 | F9: 0.050505051
A10: Florida | B10: 0.048818182 | C10: 0.072866391 | D10: 0.06336831 | E10: 0.06336831 | F10: 0.080808081
A11: Georgia, Maryland, Virginia, West Virginia | C11: 0.06862319 | D11: 0.065548173 | E11: 0.065548173 | F11: 0.060606061
A12: South Carolina | B12: 0.018727273 | C12: 0.033522428 | D12: 0.034855166 | E12: 0.034855166 | F12: 0.03030303
A13: Alabama, Kentucky, Tennessee | C13: 0.090273807 | D13: 0.093484702 | E13: 0.093484702 | F13: 0.080808081
A14: Arkansas and Oklahoma | C14: 0.025550701 | D14: 0.03099178 | E14: 0.03099178 | F14: 0.04040404
A15: Texas | B15: 0.18454545 | C15: 0.13427271 | D15: 0.13128518 | E15: 0.13128518 | F15: 0.12121212
A16: Arizona and New Mexico | C16: 0.034734771 | D16: 0.035189335 | E16: 0.035189335 | F16: 0.04040404
A17: Colorado and Wyoming | C17: 0.032149965 | D17: 0.031911431 | E17: 0.031911431 | F17: 0.04040404
A18: Montana, Nevada, Utah | C18: 0.028021136 | D18: 0.031325348 | E18: 0.031325348 | F18: 0.050505051
A19: California | B19: 0.11181818 | C19: 0.10224855 | D19: 0.1094635 | E19: 0.1094635 | F19: 0.070707071
A20: Oregon and Washington | C20: 0.016675435 | D20: 0.014223674 | E20: 0.014223674 | F20: 0.04040404
